Workbook

Sheet KEEPER LIST for 2026
A1: SUMMARY
A2: Round | B2: Player | C2: Position | D2: League Member | F2: 2025 Status | G2: 2026 Status | H2: 2027 Status | J2: 2026 Round to Keep | L2: Kept Last year
A3: 9 | B3: Matthew Stafford | C3: QB | D3: Colin Tracy | F3: 1 of 3 | G3: 2 of 3 | H3: 3 of 3 | J3: =IF(A3="FA",9,A3-1) -> 8
A4: =_xlfn.XLOOKUP(B4,'2025 Draft'!C:C,'2025 Draft'!A:A) -> 11 | B4: Bucky Irving | C4: RB | D4: Colin Tracy | F4: 1 of 3 | G4: 2 of 3 | H4: 3 of 3 | J4: =IF(A4="FA",9,A4-1) -> 10
A5: =_xlfn.XLOOKUP(B5,'2025 Draft'!C:C,'2025 Draft'!A:A) -> 2 | B5: Omarion Hampton | C5: RB | D5: Colin Tracy | F5: 1 of 3 | G5: 2 of 3 | H5: 3 of 3 | J5: =IF(A5="FA",9,A5-1) -> 1 | K5: TRADE
A6: =_xlfn.XLOOKUP(B6,'2025 Draft'!C:C,'2025 Draft'!A:A) -> 1 | B6: CeeDee Lamb | C6: WR | D6: Colin Tracy | F6: 1 of 3 | G6: 2 of 3 | H6: 3 of 3 | J6: =IF(A6="FA",9,A6-1) -> 0
A7: =_xlfn.XLOOKUP(B7,'2025 Draft'!C:C,'2025 Draft'!A:A) -> 7 | B7: Chris Olave | C7: WR | D7: Colin Tracy | F7: 1 of 3 | G7: 2 of 3 | H7: 3 of 3 | J7: =IF(A7="FA",9,A7-1) -> 6
A8: =_xlfn.XLOOKUP(B8,'2025 Draft'!C:C,'2025 Draft'!A:A) -> 9 | B8: Trey McBride | C8: TE | D8: Colin Tracy | F8: 2 of 3 | G8: 3 of 3 | H8: N/A | J8: =IF(A8="FA",9,A8-1) -> 8
A9: =_xlfn.XLOOKUP(B9,'2025 Draft'!C:C,'2025 Draft'!A:A) -> 10 | B9: Jauan Jennings | C9: WR | D9: Colin Tracy | F9: 1 of 3 | G9: 2 of 3 | H9: 3 of 3 | J9: =IF(A9="FA",9,A9-1) -> 9
A10: 9 | B10: Tyrone Tracy Jr | C10: RB | D10: Colin Tracy | F10: 1 of 3 | G10: 2 of 3 | H10: 3 of 3 | J10: =IF(A10="FA",9,A10-1) -> 8
A11: 9 | B11: Vikings | C11: D/ST | D11: Colin Tracy | F11: 1 of 3 | G11: 2 of 3 | H11: 3 of 3 | J11: =IF(A11="FA",9,A11-1) -> 8
A12: =_xlfn.XLOOKUP(B12,'2025 Draft'!C:C,'2025 Draft'!A:A) -> 2 | B12: Davante Adams | C12: WR | D12: Colin Tracy | F12: 1 of 3 | G12: 2 of 3 | H12: 3 of 3 | J12: =IF(A12="FA",9,A12-1) -> 1
A13: =_xlfn.XLOOKUP(B13,'2025 Draft'!C:C,'2025 Draft'!A:A) -> 4 | B13: DK Metcalf | C13: WR | D13: Colin Tracy | F13: 1 of 3 | G13: 2 of 3 | H13: 3 of 3 | J13: =IF(A13="FA",9,A13-1) -> 3
A14: =_xlfn.XLOOKUP(B14,'2025 Draft'!C:C,'2025 Draft'!A:A) -> 7 | B14: David Montgomery | C14: RB | D14: Colin Tracy | F14: 1 of 3 | G14: 2 of 3 | H14: 3 of 3 | J14: =IF(A14="FA",9,A14-1) -> 6
A15: 9 | B15: Wan'Dale Robinson | C15: WR | D15: Colin Tracy | F15: 1 of 3 | G15: 2 of 3 | H15: 3 of 3 | J15: =IF(A15="FA",9,A15-1) -> 8
A16: =_xlfn.XLOOKUP(B16,'2025 Draft'!C:C,'2025 Draft'!A:A) -> 2 | B16: AJ Brown | C16: WR | D16: Colin Tracy | F16: 1 of 3 | G16: 2 of 3 | H16: 3 of 3 | J16: =IF(A16="FA",9,A16-1) -> 1 | K16: TRADE
A17: =_xlfn.XLOOKUP(B17,'2025 Draft'!C:C,'2025 Draft'!A:A) -> 13 | B17: Bo Nix | C17: QB | D17: Colin Tracy | F17: 1 of 3 | G17: 2 of 3 | H17: 3 of 3 | J17: =IF(A17="FA",9,A17-1) -> 12
A18: =_xlfn.XLOOKUP(B18,'2025 Draft'!C:C,'2025 Draft'!A:A) -> 3 | B18: Alvin Kamara | C18: RB | D18: Colin Tracy | F18: 1 of 3 | G18: 2 of 3 | H18: 3 of 3 | J18: =IF(A18="FA",9,A18-1) -> 2
A20: 9 | B20: Jared Goff | C20: QB | D20: Joe Murray | F20: 1 of 3 | G20: 2 of 3 | H20: 3 of 3 | J20: =IF(A20="FA",9,A20-1) -> 8
A21: =_xlfn.XLOOKUP(B21,'2025 Draft'!C:C,'2025 Draft'!A:A) -> 1 | B21: Saquon Barkley | C21: RB | D21: Joe Murray | F21: 1 of 3 | G21: 2 of 3 | H21: 3 of 3 | J21: =IF(A21="FA",9,A21-1) -> 0
A22: =_xlfn.XLOOKUP(B22,'2025 Draft'!C:C,'2025 Draft'!A:A) -> 2 | B22: James Cook | C22: RB | D22: Joe Murray | F22: 1 of 3 | G22: 2 of 3 | H22: 3 of 3 | J22: =IF(A22="FA",9,A22-1) -> 1
A23: =_xlfn.XLOOKUP(B23,'2025 Draft'!C:C,'2025 Draft'!A:A) -> 6 | B23: Jakobi Meyers | C23: WR | D23: Joe Murray | F23: 1 of 3 | G23: 2 of 3 | H23: 3 of 3 | J23: =IF(A23="FA",9,A23-1) -> 5
A24: 9 | B24: Keenan Allen | C24: WR | D24: Joe Murray | F24: 1 of 3 | G24: 2 of 3 | H24: 3 of 3 | J24: =IF(A24="FA",9,A24-1) -> 8
A25: =_xlfn.XLOOKUP(B25,'2025 Draft'!C:C,'2025 Draft'!A:A) -> 7 | B25: Travis Kelce | C25: TE | D25: Joe Murray | F25: 1 of 3 | G25: 2 of 3 | H25: 3 of 3 | J25: =IF(A25="FA",9,A25-1) -> 6
A26: =_xlfn.XLOOKUP(B26,'2025 Draft'!C:C,'2025 Draft'!A:A) -> 3 | B26: Drake London | C26: WR | D26: Joe Murray | F26: 1 of 3 | G26: 2 of 3 | H26: 3 of 3 | J26: =IF(A26="FA",9,A26-1) -> 2
A27: =_xlfn.XLOOKUP(B27,'2025 Draft'!C:C,'2025 Draft'!A:A) -> 3 | B27: TreVeyon Henderson | C27: RB | D27: Joe Murray | F27: 1 of 3 | G27: 2 of 3 | H27: 3 of 3 | J27: =IF(A27="FA",9,A27-1) -> 2 | K27: TRADE
A28: 9 | B28: Colts | C28: D/ST | D28: Joe Murray | F28: 1 of 3 | G28: 2 of 3 | H28: 3 of 3 | J28: =IF(A28="FA",9,A28-1) -> 8
A29: =_xlfn.XLOOKUP(B29,'2025 Draft'!C:C,'2025 Draft'!A:A) -> 4 | B29: D'Andre Swift | C29: RB | D29: Joe Murray | F29: 1 of 3 | G29: 2 of 3 | H29: 3 of 3 | J29: =IF(A29="FA",9,A29-1) -> 3
A30: =_xlfn.XLOOKUP(B30,'2025 Draft'!C:C,'2025 Draft'!A:A) -> 10 | B30: Jayden Daniels | C30: QB | D30: Joe Murray | F30: 1 of 3 | G30: 2 of 3 | H30: 3 of 3 | J30: =IF(A30="FA",9,A30-1) -> 9
A31: 9 | B31: Caleb Williams | C31: QB | D31: Joe Murray | F31: 1 of 3 | G31: 2 of 3 | H31: 3 of 3 | J31: =IF(A31="FA",9,A31-1) -> 8
A32: 9 | B32: Tre Tucker | C32: WR | D32: Joe Murray | F32: 1 of 3 | G32: 2 of 3 | H32: 3 of 3 | J32: =IF(A32="FA",9,A32-1) -> 8
A33: 9 | B33: Calvin Austin | C33: WR | D33: Joe Murray | F33: 1 of 3 | G33: 2 of 3 | H33: 3 of 3 | J33: =IF(A33="FA",9,A33-1) -> 8
A34: 9 | B34: Brenton Strange | C34: TE | D34: Joe Murray | F34: 1 of 3 | G34: 2 of 3 | H34: 3 of 3 | J34: =IF(A34="FA",9,A34-1) -> 8
A35: 9 | B35: Falcons | C35: D/ST | D35: Joe Murray | F35: 1 of 3 | G35: 2 of 3 | H35: 3 of 3 | J35: =IF(A35="FA",9,A35-1) -> 8
A36: =_xlfn.XLOOKUP(B36,'2025 Draft'!C:C,'2025 Draft'!A:A) -> 3 | B36: Marvin Harrison Jr | C36: WR | D36: Joe Murray | F36: 1 of 3 | G36: 2 of 3 | H36: 3 of 3 | J36: =IF(A36="FA",9,A36-1) -> 2
A38: 9 | B38: Jacoby Brissett | C38: QB | D38: Scott Johnston | F38: 1 of 3 | G38: 2 of 3 | H38: 3 of 3 | J38: =IF(A38="FA",9,A38-1) -> 8
A39: =_xlfn.XLOOKUP(B39,'2025 Draft'!C:C,'2025 Draft'!A:A) -> 8 | B39: Kyren Williams | C39: RB | D39: Scott Johnston | F39: 1 of 3 | G39: 2 of 3 | H39: 3 of 3 | J39: =IF(A39="FA",9,A39-1) -> 7
A40: 9 | B40: Kyle Monangai | C40: RB | D40: Scott Johnston | F40: 1 of 3 | G40: 2 of 3 | H40: 3 of 3 | J40: =IF(A40="FA",9,A40-1) -> 8
A41: =_xlfn.XLOOKUP(B41,'2025 Draft'!C:C,'2025 Draft'!A:A) -> 3 | B41: Terry McLaurin | C41: WR | D41: Scott Johnston | F41: 1 of 3 | G41: 2 of 3 | H41: 3 of 3 | J41: =IF(A41="FA",9,A41-1) -> 2
A42: 9 | B42: Michael Wilson | C42: WR | D42: Scott Johnston | F42: 1 of 3 | G42: 2 of 3 | H42: 3 of 3 | J42: =IF(A42="FA",9,A42-1) -> 8
...

Sheet 2025 Draft
A1: Round | B1: Pick | C1: Player | D1: Position | E1: Team | F1: League Member | H1: Total
A2: 1 | B2: 1 | C2: CeeDee Lamb | D2: WR | E2: DAL | F2: Colin | H2: 1 | S2: Zach | T2: =COUNTIF($F$2:$F$161,S2) -> 16
A3: 1 | B3: 2 | C3: Jahmyr Gibbs | D3: RB | E3: DET | F3: Stefan | H3: 2 | S3: Josh | T3: =COUNTIF($F$2:$F$161,S3) -> 16
A4: 1 | B4: 3 | C4: Bijan Robinson | D4: RB | E4: ATL | F4: Witte | H4: 3 | S4: Colin | T4: =COUNTIF($F$2:$F$161,S4) -> 16
A5: 1 | B5: 4 | C5: Saquon Barkley | D5: RB | E5: PHI | F5: Joe | H5: 4 | S5: Kyle | T5: =COUNTIF($F$2:$F$161,S5) -> 16
A6: 1 | B6: 5 | C6: Christian McCaffrey | D6: RB | E6: SF | F6: Elbe | H6: 5 | S6: Elbe | T6: =COUNTIF($F$2:$F$161,S6) -> 16
A7: 1 | B7: 6 | C7: Ashton Jeanty | D7: RB | E7: LAV | F7: Kyle | H7: 6 | S7: Witte | T7: =COUNTIF($F$2:$F$161,S7) -> 16
A8: 1 | B8: 7 | C8: Amon-Ra St. Brown | D8: WR | E8: DET | F8: Josh | H8: 7 | S8: Joe | T8: =COUNTIF($F$2:$F$161,S8) -> 16
A9: 1 | B9: 8 | C9: Derrick Henry | D9: RB | E9: BAL | F9: Scott | H9: 8 | S9: Scott | T9: =COUNTIF($F$2:$F$161,S9) -> 16
A10: 1 | B10: 9 | C10: Malik Nabers | D10: WR | E10: NYG | F10: Greg | H10: 9 | S10: Greg | T10: =COUNTIF($F$2:$F$161,S10) -> 16
A11: 1 | B11: 10 | C11: Jonathan Taylor | D11: RB | E11: IND | F11: Greg | H11: 10 | S11: Stefan | T11: =COUNTIF($F$2:$F$161,S11) -> 16
A12: 2 | B12: 11 | C12: AJ Brown | D12: WR | E12: PHI | F12: Zach | H12: 11
A13: 2 | B13: 12 | C13: Lamar Jackson | D13: QB | E13: BAL | F13: Greg | H13: 12
A14: 2 | B14: 13 | C14: Tyreek Hill | D14: WR | E14: MIA | F14: Joe | H14: 13
A15: 2 | B15: 14 | C15: Ja'Marr Chase | D15: WR | E15: CIN | F15: Josh | H15: 14
A16: 2 | B16: 15 | C16: Josh Jacobs | D16: RB | E16: GB | F16: Witte | H16: 15
A17: 2 | B17: 16 | C17: Tee Higgins | D17: WR | E17: CIN | F17: Elbe | H17: 16
A18: 2 | B18: 17 | C18: James Cook | D18: RB | E18: BUF | F18: Joe | H18: 17
A19: 2 | B19: 18 | C19: Omarion Hampton | D19: RB | E19: LAC | F19: Witte | H19: 18
A20: 2 | B20: 19 | C20: Josh Allen | D20: QB | E20: BUF | F20: Stefan | H20: 19
A21: 2 | B21: 20 | C21: Davante Adams | D21: WR | E21: LAR | F21: Colin | H21: 20
A22: 3 | B22: 21 | C22: Alvin Kamara | D22: RB | E22: NO | F22: Colin | H22: 21
A23: 3 | B23: 22 | C23: Mike Evans | D23: WR | E23: TB | F23: Stefan | H23: 22
... A120: 12 | B120: 119 | C120: Dak Prescott | D120: QB | E120: DAL | F120: Stefan | H120: 119
A121: 12 | B121: 120 | C121: Trey Benson | F121: Zach | H121: 120
A122: 13 | B122: 121 | C122: Kyler Murray | D122: QB | E122: ARI | F122: Colin | H122: 121
A123: 13 | B123: 122 | C123: Woody Marks | D123: RB | E123: HOU | F123: Stefan | H123: 122
A124: 13 | B124: 123 | C124: Chris Godwin | D124: WR | E124: TB | F124: Witte | H124: 123
A125: 13 | B125: 124 | C125: David Njoku | D125: TE | E125: CLE | F125: Joe | H125: 124
A126: 13 | B126: 125 | C126: Bo Nix | D126: QB | E126: DEN | F126: Elbe | H126: 125
A127: 13 | B127: 126 | C127: Drake Maye | D127: QB | E127: NE | F127: Kyle | H127: 126
A128: 13 | B128: 127 | C128: Brian Robinson Jr | D128: RB | E128: SF | F128: Josh | H128: 127
A129: 13 | B129: 128 | C129: Braelon Allen | D129: RB | E129: NYJ | F129: Scott | H129: 128
A130: 13 | B130: 129 | C130: Jerome Ford | D130: RB | E130: CLE | F130: Greg | H130: 129
A131: 13 | B131: 130 | C131: PIT STEELERS | D131: DEF | E131: PIT | F131: Zach | H131: 130
A132: 14 | B132: 131 | C132: Ollie Gordon | D132: RB | E132: MIA | F132: Zach | H132: 131
A133: 14 | B133: 132 | C133: Tyler Allgeier | D133: RB | F133: Greg | H133: 132
A134: 14 | B134: 133 | C134: Tre' Harris | D134: WR | E134: LAC | F134: Scott | H134: 133
A135: 14 | B135: 134 | C135: Pat Bryant | D135: WR | E135: DEN | F135: Josh | H135: 134
A136: 14 | B136: 135 | C136: JJ McCarthy | D136: QB | E136: MIN | F136: Kyle | H136: 135
...

Sheet KEEPER LIST for 2025
A1: SUMMARY
A2: Round | B2: Player | C2: Position | D2: League Member | F2: 2024 Status | G2: 2025 Status | H2: 2026 Status | J2: 2025 Round to Keep | L2: Kept Last year
A3: =_xlfn.XLOOKUP(B3,'2024 Draft'!C:C,'2024 Draft'!A:A) -> 9 | B3: CJ Stroud | C3: QB | D3: Colin Tracy | F3: 2 of 3 | G3: 3 of 3 | H3: N/A | J3: =IF(A3="FA",9,A3-1) -> 8 | L3: x
A4: =_xlfn.XLOOKUP(B4,'2024 Draft'!C:C,'2024 Draft'!A:A) -> 3 | B4: Rachaad White | C4: RB | D4: Colin Tracy | F4: 1 of 3 | G4: 2 of 3 | H4: 3 of 3 | J4: =IF(A4="FA",9,A4-1) -> 2
A5: =_xlfn.XLOOKUP(B5,'2024 Draft'!C:C,'2024 Draft'!A:A) -> 6 | B5: Rhamondre Stevenson | C5: RB | D5: Colin Tracy | F5: 1 of 3 | G5: 2 of 3 | H5: 3 of 3 | J5: =IF(A5="FA",9,A5-1) -> 5
A6: FA | B6: Keenan Allen | C6: WR | D6: Colin Tracy | F6: 1 of 3 | G6: 2 of 3 | H6: 3 of 3 | J6: =IF(A6="FA",9,A6-1) -> 9
A7: FA | B7: Quentin Johnston | C7: WR | D7: Colin Tracy | F7: 1 of 3 | G7: 2 of 3 | H7: 3 of 3 | J7: =IF(A7="FA",9,A7-1) -> 9
A8: FA | B8: Hunter Henry | C8: TE | D8: Colin Tracy | F8: 1 of 3 | G8: 2 of 3 | H8: 3 of 3 | J8: =IF(A8="FA",9,A8-1) -> 9
A9: =_xlfn.XLOOKUP(B9,'2024 Draft'!C:C,'2024 Draft'!A:A) -> 10 | B9: Trey McBride | C9: TE | D9: Colin Tracy | F9: 1 of 3 | G9: 2 of 3 | H9: 3 of 3 | J9: =IF(A9="FA",9,A9-1) -> 9 | L9: x-Stefan
A10: FA | B10: Elijah Moore | C10: WR | D10: Colin Tracy | F10: 1 of 3 | G10: 2 of 3 | H10: 3 of 3 | J10: =IF(A10="FA",9,A10-1) -> 9
A11: FA | B11: Dolphins | C11: D/ST | D11: Colin Tracy | F11: 1 of 3 | G11: 2 of 3 | H11: 3 of 3 | J11: =IF(A11="FA",9,A11-1) -> 9
A12: =_xlfn.XLOOKUP(B12,'2024 Draft'!C:C,'2024 Draft'!A:A) -> 8 | B12: Jonathon Brooks | C12: RB | D12: Colin Tracy | F12: 1 of 3 | G12: 2 of 3 | H12: 3 of 3 | J12: =IF(A12="FA",9,A12-1) -> 7
A13: FA | B13: Packers | C13: D/ST | D13: Colin Tracy | F13: 1 of 3 | G13: 2 of 3 | H13: 3 of 3 | J13: =IF(A13="FA",9,A13-1) -> 9
A14: FA | B14: Christian Watson | C14: WR | D14: Colin Tracy | F14: 1 of 3 | G14: 2 of 3 | H14: 3 of 3 | J14: =IF(A14="FA",9,A14-1) -> 9
A15: FA | B15: Cedric Tillman | C15: WR | D15: Colin Tracy | F15: 1 of 3 | G15: 2 of 3 | H15: 3 of 3 | J15: =IF(A15="FA",9,A15-1) -> 9
A16: FA | B16: Jameis Winston | C16: QB | D16: Colin Tracy | F16: 1 of 3 | G16: 2 of 3 | H16: 3 of 3 | J16: =IF(A16="FA",9,A16-1) -> 9
A17: FA | B17: Devin Singletary | C17: RB | D17: Colin Tracy | F17: 1 of 3 | G17: 2 of 3 | H17: 3 of 3 | J17: =IF(A17="FA",9,A17-1) -> 9
A18: FA | B18: Sterling Shepard | C18: WR | D18: Colin Tracy | F18: 1 of 3 | G18: 2 of 3 | H18: 3 of 3 | J18: =IF(A18="FA",9,A18-1) -> 9
A20: FA | B20: Russell Wilson | C20: QB | D20: Joe Murray | F20: 1 of 3 | G20: 2 of 3 | H20: 3 of 3 | J20: =IF(A20="FA",9,A20-1) -> 9
A21: =_xlfn.XLOOKUP(B21,'2024 Draft'!C:C,'2024 Draft'!A:A) -> 4 | B21: James Cook | C21: RB | D21: Joe Murray | F21: 1 of 3 | G21: 2 of 3 | H21: 3 of 3 | J21: =IF(A21="FA",9,A21-1) -> 3
A22: FA | B22: Najee Harris | C22: RB | D22: Joe Murray | F22: 1 of 3 | G22: 2 of 3 | H22: 3 of 3 | J22: =IF(A22="FA",9,A22-1) -> 9
A23: =_xlfn.XLOOKUP(B23,'2024 Draft'!C:C,'2024 Draft'!A:A) -> 5 | B23: Mike Evans | C23: WR | D23: Joe Murray | F23: 2 of 3 | G23: 3 of 3 | H23: N/A | J23: =IF(A23="FA",9,A23-1) -> 4 | L23: x
A24: =_xlfn.XLOOKUP(B24,'2024 Draft'!C:C,'2024 Draft'!A:A) -> 4 | B24: Calvin Ridley | C24: WR | D24: Joe Murray | F24: 1 of 3 | G24: 2 of 3 | H24: 3 of 3 | J24: =IF(A24="FA",9,A24-1) -> 3 | K24: TRADE
A25: =_xlfn.XLOOKUP(B25,'2024 Draft'!C:C,'2024 Draft'!A:A) -> 11 | B25: Dalton Kincaid | C25: TE | D25: Joe Murray | F25: 2 of 3 | G25: 3 of 3 | H25: N/A | J25: =IF(A25="FA",9,A25-1) -> 10 | L25: x
A26: =_xlfn.XLOOKUP(B26,'2024 Draft'!C:C,'2024 Draft'!A:A) -> 7 | B26: Jayden Reed | C26: WR | D26: Joe Murray | F26: 1 of 3 | G26: 2 of 3 | H26: 3 of 3 | J26: =IF(A26="FA",9,A26-1) -> 6
A27: FA | B27: Ameer Abdullah | C27: RB | D27: Joe Murray | F27: 1 of 3 | G27: 2 of 3 | H27: 3 of 3 | J27: =IF(A27="FA",9,A27-1) -> 9
A28: FA | B28: Bills | C28: D/ST | D28: Joe Murray | F28: 1 of 3 | G28: 2 of 3 | H28: 3 of 3 | J28: =IF(A28="FA",9,A28-1) -> 9
A29: FA | B29: Allen Lazard | C29: WR | D29: Joe Murray | F29: 1 of 3 | G29: 2 of 3 | H29: 3 of 3 | J29: =IF(A29="FA",9,A29-1) -> 9
A30: FA | B30: Tank Bigsby | C30: RB | D30: Joe Murray | F30: 1 of 3 | G30: 2 of 3 | H30: 3 of 3 | J30: =IF(A30="FA",9,A30-1) -> 9
A31: FA | B31: Ricky Pearsall | C31: WR | D31: Joe Murray | F31: 1 of 3 | G31: 2 of 3 | H31: 3 of 3 | J31: =IF(A31="FA",9,A31-1) -> 9
A32: FA | B32: Justin Herbert | C32: QB | D32: Joe Murray | F32: 1 of 3 | G32: 2 of 3 | H32: 3 of 3 | J32: =IF(A32="FA",9,A32-1) -> 9
A33: FA | B33: Cole Kmet | C33: TE | D33: Joe Murray | F33: 1 of 3 | G33: 2 of 3 | H33: 3 of 3 | J33: =IF(A33="FA",9,A33-1) -> 9
A34: FA | B34: Mike Desicki | C34: TE | D34: Joe Murray | F34: 1 of 3 | G34: 2 of 3 | H34: 3 of 3 | J34: =IF(A34="FA",9,A34-1) -> 9
A35: FA | B35: Gus Edwards | C35: RB | D35: Joe Murray | F35: 1 of 3 | G35: 2 of 3 | H35: 3 of 3 | J35: =IF(A35="FA",9,A35-1) -> 9
A36: =_xlfn.XLOOKUP(B36,'2024 Draft'!C:C,'2024 Draft'!A:A) -> 6 | B36: David Montgomery | C36: RB | D36: Joe Murray | F36: 1 of 3 | G36: 2 of 3 | H36: 3 of 3 | J36: =IF(A36="FA",9,A36-1) -> 5
A38: =_xlfn.XLOOKUP(B38,'2024 Draft'!C:C,'2024 Draft'!A:A) -> 4 | B38: Josh Allen | C38: QB | D38: Scott Johnston | F38: 1 of 3 | G38: 2 of 3 | H38: 3 of 3 | J38: =IF(A38="FA",9,A38-1) -> 3
A39: =_xlfn.XLOOKUP(B39,'2024 Draft'!C:C,'2024 Draft'!A:A) -> 1 | B39: Jahmyr Gibbs | C39: RB | D39: Scott Johnston | F39: 1 of 3 | G39: 2 of 3 | H39: 3 of 3 | J39: =IF(A39="FA",9,A39-1) -> 0
A40: =_xlfn.XLOOKUP(B40,'2024 Draft'!C:C,'2024 Draft'!A:A) -> 11 | B40: Rico Dowdle | C40: RB | D40: Scott Johnston | F40: 1 of 3 | G40: 2 of 3 | H40: 3 of 3 | J40: =IF(A40="FA",9,A40-1) -> 10
A41: =_xlfn.XLOOKUP(B41,'2024 Draft'!C:C,'2024 Draft'!A:A) -> 2 | B41: Davante Adams | C41: WR | D41: Scott Johnston | F41: 1 of 3 | G41: 2 of 3 | H41: 3 of 3 | J41: =IF(A41="FA",9,A41-1) -> 1
A42: =_xlfn.XLOOKUP(B42,'2024 Draft'!C:C,'2024 Draft'!A:A) -> 13 | B42: Puka Nacua | C42: WR | D42: Scott Johnston | F42: 2 of 3 | G42: 3 of 3 | H42: N/A | J42: =IF(A42="FA",9,A42-1) -> 12 | L42: x
...

Sheet 2024 Draft
A1: Round | B1: Pick | C1: Player | D1: Position | E1: Team | F1: League Member | G1: Comments
A2: 1 | B2: 1 | C2: CeeDee Lamb | D2: WR | E2: DAL | F2: Zach | G2: [General surprise] | U2: Zach | V2: =COUNTIF($F$2:$F$174,U2) -> 16
A3: 1 | B3: 2 | C3: Christian McCaffrey | D3: RB | E3: SF | F3: Josh | G3: "I'll take McCaffree" Colin, right after Josh took jim | U3: Josh | V3: =COUNTIF($F$2:$F$174,U3) -> 16
A4: 1 | B4: 3 | C4: Tyreek Hill | D4: WR | E4: MIA | F4: Colin | U4: Colin | V4: =COUNTIF($F$2:$F$174,U4) -> 16
A5: 1 | B5: 4 | C5: Bijan RobiNson | D5: RB | E5: ATL | F5: Kyle | U5: Kyle | V5: =COUNTIF($F$2:$F$174,U5) -> 16
A6: 1 | B6: 5 | C6: Breece Hall | D6: RB | E6: NYJ | F6: Elbe | U6: Elbe | V6: =COUNTIF($F$2:$F$174,U6) -> 16
A7: 1 | B7: 6 | C7: AJ Brown | D7: WR | E7: PHI | F7: Witte | G7: "I got Saquon" Joe, during Witte's turn | U7: Witte | V7: =COUNTIF($F$2:$F$174,U7) -> 16
A8: 1 | B8: 7 | C8: Saquon Barkley | D8: RB | E8: PHI | F8: Joe | U8: Joe | V8: =COUNTIF($F$2:$F$174,U8) -> 16
A9: 1 | B9: 8 | C9: Jahmyr Gibbs | D9: RB | E9: DET | F9: Scott | G9: "That's a good pick, Scott" Colin | U9: Scott | V9: =COUNTIF($F$2:$F$174,U9) -> 16
A10: 1 | B10: 9 | C10: Travis Etienne Jr. | D10: RB | E10: JAX | F10: Greg | G10: "Another good one" Colin; "I don't feel good about this" GG | U10: Greg | V10: =COUNTIF($F$2:$F$174,U10) -> 16
A11: 1 | B11: 10 | C11: Chris Olave | D11: WR | E11: NO | F11: Stefan | G11: [Joe goes to get beer] "Oh yeah, you don't have a pick next round" Elbe to Joe; Joe, "Yeah, Zach fleeced me" | U11: Stefan | V11: =COUNTIF($F$2:$F$174,U11) -> 16
A12: 2 | B12: 11 | C12: Marvin Harrison Jr. | D12: WR | E12: ARI | F12: Stefan | G12: [Joe trips coming back with beer]; "Those are reaches brotha" Colin to Stefan; "They aren't reaches because they won't be there when I pick next" Stefan
A13: 2 | B13: 12 | C13: Derrick Henry | D13: RB | E13: BAL | F13: Greg | G13: "Early" Stefan "One of the best available out there" Kyle "Whateva brotha" Colin, again using "brotha" within 3 minutes
A14: 2 | B14: 13 | C14: Davante Adams | D14: WR | E14: LAV | F14: Scott | G14: "AJ Brown, really?" Stefan to Witte; [Witte tries to facetime in]
A15: 2 | B15: 14 | C15: Cooper Kupp | D15: WR | E15: LAR | F15: Josh | G15: "That doesn't look like Canada it looks like Hawaii" Elbe to Witte; "Ask him about Katie F.'s head" Kyle
A16: 2 | B16: 15 | C16: Amon-Ra St. Brown | D16: WR | E16: DET | F16: Witte | G16: "Witte, nice keeper in the 2nd round" Stefan; "Are you keeping him next year?" GG; "Witte, are you shitting?" collective
A17: 2 | B17: 16 | C17: DK Metcalf | D17: WR | E17: SEA | F17: Elbe | G17: "In a keeper league, this is when the league is won" Colin; [talk of soft tissue injuries]; "My guy has a lot of children he has to feed, so he isn't getting hurt" Colin; "This is a tough one, boys" Elbe; "Where is Amari Rodgers playing?" Colin to Joe
A18: 2 | B18: 17 | C18: Malik Nabers | D18: WR | E18: NYG | F18: Kyle | G18: "Danny Dimes throwing over his head 10 yds every time" Elbe "I saw him throw over his head a lot" Elbe under his breath; "Scared money aint make no money" Kyle
A19: 2 | B19: 18 | C19: Josh Jacobs | D19: RB | E19: GB | F19: Colin | G19: "This is a tough spot for you" Kyle to Colin; [Joe sings 'Will You Be My Hero Baby']; [Colin has angst over pick]; "Ok change of scenary I'm going Josh Jacobs" "That's high up there. Second Round?" Stefan to Colin
A20: 2 | B20: 19 | C20: Brandon Aiyuk | D20: WR | E20: SF | F20: Zach
A21: 2 | B21: 20 | C21: Lamar Jackson | D21: QB | E21: BAL | F21: Zach | G21: [WHOA - collective] "He could have got him on the way back" Kyle "This has to be a tight end" Kyle
A22: 3 | B22: 21 | C22: Rashee Rice | D22: WR | E22: KC | F22: Zach | G22: "That's a really good pick" kyle "That's a reach!" Colin "When you have that many picks in a row you can reach" Stefan "His receviers look pretty good" Elbe …. "He don't have any other running backs" Elbe in discussion re: Dolphins rbs
A23: 3 | B23: 22 | C23: Ja'Marr Chase | D23: WR | E23: CIN | F23: Josh
A24: 3 | B24: 23 | C24: Rachaad White | D24: RB | E24: TB | F24: Colin | G24: "I'm taking…hmmmm…" [trails off] Colin; "Have fun with that. The most inefficient RB last year." Stefan
A25: 3 | B25: 24 | C25: DeEbo Samuel Sr. | D25: WR | E25: SF | F25: Kyle | G25: "How's his vagina doing? That boy always pulling his vagina" Joe
A26: 3 | B26: 25 | C26: Jalen Hurts | D26: QB | E26: PHi | F26: Elbe | G26: "Alright, give him to me, Jalen Hurts" Elbe; "Get off the shitter, Witte" Elbe
A27: 3 | B27: 26 | C27: Stefon Diggs | D27: WR | E27: BUF | F27: Witte | G27: "They're all dog shit. I need a RB." Colin; "You don’t need to, it’s a PPR league." Stefan
A28: 3 | B28: 27 | C28: Travis Kelce | D28: TE | E28: KC | F28: Joe | G28: "Hey elbe, good pick." Stefan "He's especially good in PPR leagues" Stefan to Elbe; "Come on guys that was a couple years ago, now" Elbe; "I double TE'ed it" Joe; "That might be the worst pick of the draft" Stefan "Kincaid is an 11th round keeper, yall can suck my nuts" Joe; [discussion of Joe's nuts ensue]
A29: 3 | B29: 28 | C29: Alvin Kamara | D29: RB | E29: NO | F29: Scott
A30: 3 | B30: 29 | C30: Jaylen Waddle | D30: WR | E30: MIA | F30: Greg
A31: 3 | B31: 30 | C31: Mark Andrews | D31: TE | E31: BAL | F31: Stefan | G31: "Make sure you go get Joe Mixon you were just shitting on" Colin; "I don’t want him" Stefan "He won you a title last year, show some respect" Kyle to Stefan
A32: 4 | B32: 31 | C32: Kenneth Walker III | D32: RB | E32: SEA | F32: Stefan
A33: 4 | B33: 32 | C33: Jonathan Taylor | D33: RB | E33: IND | F33: Greg
A34: 4 | B34: 33 | C34: Josh Allen | D34: QB | E34: BUF | F34: Scott | G34: "Great pick, Scott" Colin "Scott's building a squad" Colin "That makes me nervous" Scott
A35: 4 | B35: 34 | C35: James Cook | D35: RB | E35: BUF | F35: Joe | G35: "James Cookie monster" Joe
A36: 4 | B36: 35 | C36: Patrick Mahomes | D36: QB | E36: KC | F36: Witte | G36: [Greg and Stefan wispering]; [Colin talking about having 4 balls] "Let's see 'em" Joe to Colin
A37: 4 | B37: 36 | C37: Joe Mixon | D37: RB | E37: HOU | F37: Zach
A38: 4 | B38: 37 | C38: Calvin Ridley | D38: WR | E38: TEN | F38: Kyle
A39: 4 | B39: 38 | C39: Amari Cooper | D39: WR | E39: CLE | F39: Colin | G39: "Dashaun can't throw the ball anymore" Elbe "Shut up man he's fine" Colin
A40: 4 | B40: 39 | C40: Drake London | D40: WR | E40: ATL | F40: Josh
...

Sheet KEEPER LIST for 2024
A1: SUMMARY | F1: TERM
A2: Round | B2: Player | C2: Position | D2: League Member | F2: 2023 Status | G2: 2024 Status | H2: 2025 Status | J2: 2024 Round to Keep
A3: FA | B3: CJ Stroud | C3: QB | D3: Colin Tracy | F3: 1 of 3 | G3: 2 of 3 | H3: 3 of 3 | J3: =IF(A3="FA",9,A3-1) -> 9
A4: =_xlfn.XLOOKUP(B4,'2023 Draft'!$C$3:$C$162,'2023 Draft'!$A$3:$A$162) -> 2 | B4: Breece Hall | C4: RB | D4: Colin Tracy | F4: 1 of 3 | G4: 2 of 3 | H4: 3 of 3 | J4: =IF(A4="FA",9,A4-1) -> 1
A5: =_xlfn.XLOOKUP(B5,'2023 Draft'!$C$3:$C$162,'2023 Draft'!$A$3:$A$162) -> 7 | B5: James Conner | C5: RB | D5: Colin Tracy | F5: 1 of 3 | G5: 2 of 3 | H5: 3 of 3 | J5: =IF(A5="FA",9,A5-1) -> 6
A6: =_xlfn.XLOOKUP(B6,'2023 Draft'!$C$3:$C$162,'2023 Draft'!$A$3:$A$162) -> 1 | B6: AJ Brown | C6: WR | D6: Colin Tracy | F6: 1 of 3 | G6: 2 of 3 | H6: 3 of 3 | J6: =IF(A6="FA",9,A6-1) -> 0
A7: FA | B7: Curtis Samuel | C7: WR | D7: Colin Tracy | F7: 1 of 3 | G7: 2 of 3 | H7: 3 of 3 | J7: =IF(A7="FA",9,A7-1) -> 9
A8: FA | B8: Dalton Schultz | C8: TE | D8: Colin Tracy | F8: 1 of 3 | G8: 2 of 3 | H8: 3 of 3 | J8: =IF(A8="FA",9,A8-1) -> 9
A9: =_xlfn.XLOOKUP(B9,'2023 Draft'!$C$3:$C$162,'2023 Draft'!$A$3:$A$162) -> 5 | B9: Kenneth Walker | C9: RB | D9: Colin Tracy | F9: 1 of 3 | G9: 2 of 3 | H9: 3 of 3 | J9: =IF(A9="FA",9,A9-1) -> 4
A10: =_xlfn.XLOOKUP(B10,'2023 Draft'!$C$3:$C$162,'2023 Draft'!$A$3:$A$162) -> 14 | B10: Travis Etienne Jr. | C10: RB | D10: Colin Tracy | F10: 3 of 3 | G10: N/A | H10: N/A | J10: N/A
A11: 15 | B11: Cowboys | C11: D/ST | D11: Colin Tracy | F11: 1 of 3 | G11: 2 of 3 | H11: 3 of 3 | J11: =IF(A11="FA",9,A11-1) -> 14
A12: =_xlfn.XLOOKUP(B12,'2023 Draft'!$C$3:$C$162,'2023 Draft'!$A$3:$A$162) -> 6 | B12: Amari Cooper | C12: WR | D12: Colin Tracy | F12: 2 of 3 | G12: 3 of 3 | H12: N/A | J12: =IF(A12="FA",9,A12-1) -> 5
A13: =_xlfn.XLOOKUP(B13,'2023 Draft'!$C$3:$C$162,'2023 Draft'!$A$3:$A$162) -> 11 | B13: Jamaal Williams | C13: RB | D13: Colin Tracy | F13: 1 of 3 | G13: 2 of 3 | H13: 3 of 3 | J13: =IF(A13="FA",9,A13-1) -> 10
A14: =_xlfn.XLOOKUP(B14,'2023 Draft'!$C$3:$C$162,'2023 Draft'!$A$3:$A$162) -> 8 | B14: Christian Kirk | C14: WR | D14: Colin Tracy | F14: 1 of 3 | G14: 2 of 3 | H14: 3 of 3 | J14: =IF(A14="FA",9,A14-1) -> 7
A15: =_xlfn.XLOOKUP(B15,'2023 Draft'!$C$3:$C$162,'2023 Draft'!$A$3:$A$162) -> 15 | B15: Zay Jones | C15: WR | D15: Colin Tracy | F15: 1 of 3 | G15: 2 of 3 | H15: 3 of 3 | J15: =IF(A15="FA",9,A15-1) -> 14
A16: FA | B16: Cole Kmet | C16: TE | D16: Colin Tracy | F16: 1 of 3 | G16: 2 of 3 | H16: 3 of 3 | J16: =IF(A16="FA",9,A16-1) -> 9
A17: FA | B17: Jeff Wilson Jr. | C17: RB | D17: Colin Tracy | F17: 1 of 3 | G17: 2 of 3 | H17: 3 of 3 | J17: =IF(A17="FA",9,A17-1) -> 9
A18: FA | B18: Tyler Higbee | C18: TE | D18: Colin Tracy | F18: 1 of 3 | G18: 2 of 3 | H18: 3 of 3 | J18: =IF(A18="FA",9,A18-1) -> 9
A19: =_xlfn.XLOOKUP(B19,'2023 Draft'!$C$3:$C$162,'2023 Draft'!$A$3:$A$162) -> 4 | B19: Joe Burrow | C19: QB | D19: Colin Tracy | F19: 1 of 3 | G19: 2 of 3 | H19: 3 of 3 | J19: =IF(A19="FA",9,A19-1) -> 3
A21: FA | B21: Jared Goff | C21: QB | D21: Joe Murray | F21: 1 of 3 | G21: 2 of 3 | H21: 3 of 3 | J21: =IF(A21="FA",9,A21-1) -> 9
A22: =_xlfn.XLOOKUP(B22,'2023 Draft'!$C$3:$C$162,'2023 Draft'!$A$3:$A$162) -> 2 | B22: Saquon Barkley | C22: RB | D22: Joe Murray | F22: 1 of 3 | G22: 2 of 3 | H22: 3 of 3 | J22: =IF(A22="FA",9,A22-1) -> 1
A23: =_xlfn.XLOOKUP(B23,'2023 Draft'!$C$3:$C$162,'2023 Draft'!$A$3:$A$162) -> 3 | B23: Rachaad White | C23: RB | D23: Joe Murray | F23: 1 of 3 | G23: 2 of 3 | H23: 3 of 3 | J23: =IF(A23="FA",9,A23-1) -> 2
A24: =_xlfn.XLOOKUP(B24,'2023 Draft'!$C$3:$C$162,'2023 Draft'!$A$3:$A$162) -> 1 | B24: Cooper Kupp | C24: WR | D24: Joe Murray | F24: 2 of 3 | G24: 3 of 3 | H24: N/A | J24: =IF(A24="FA",9,A24-1) -> 0
A25: =_xlfn.XLOOKUP(B25,'2023 Draft'!$C$3:$C$162,'2023 Draft'!$A$3:$A$162) -> 3 | B25: Deebo Samuel | C25: WR | D25: Joe Murray | F25: 1 of 3 | G25: 2 of 3 | H25: 3 of 3 | J25: =IF(A25="FA",9,A25-1) -> 2
A26: =_xlfn.XLOOKUP(B26,'2023 Draft'!$C$3:$C$162,'2023 Draft'!$A$3:$A$162) -> 12 | B26: Dalton Kincaid | C26: TE | D26: Joe Murray | F26: 1 of 3 | G26: 2 of 3 | H26: 3 of 3 | J26: =IF(A26="FA",9,A26-1) -> 11
A27: =_xlfn.XLOOKUP(B27,'2023 Draft'!$C$3:$C$162,'2023 Draft'!$A$3:$A$162) -> 6 | B27: Mike Evans | C27: WR | D27: Joe Murray | F27: 1 of 3 | G27: 2 of 3 | H27: 3 of 3 | J27: =IF(A27="FA",9,A27-1) -> 5
A28: =_xlfn.XLOOKUP(B28,'2023 Draft'!$C$3:$C$162,'2023 Draft'!$A$3:$A$162) -> 1 | B28: Austin Ekeler | C28: RB | D28: Joe Murray | F28: 1 of 3 | G28: 2 of 3 | H28: 3 of 3 | J28: =IF(A28="FA",9,A28-1) -> 0
A29: FA | B29: Colts | C29: D/ST | D29: Joe Murray | F29: 1 of 3 | G29: 2 of 3 | H29: 3 of 3 | J29: =IF(A29="FA",9,A29-1) -> 9
A30: =_xlfn.XLOOKUP(B30,'2023 Draft'!$C$3:$C$162,'2023 Draft'!$A$3:$A$162) -> 4 | B30: Alexander Mattison | C30: RB | D30: Joe Murray | F30: 1 of 3 | G30: 2 of 3 | H30: 3 of 3 | J30: =IF(A30="FA",9,A30-1) -> 3
A31: =_xlfn.XLOOKUP(B31,'2023 Draft'!$C$3:$C$162,'2023 Draft'!$A$3:$A$162) -> 5 | B31: Terry McLaurin | C31: WR | D31: Joe Murray | F31: 1 of 3 | G31: 2 of 3 | H31: 3 of 3 | J31: =IF(A31="FA",9,A31-1) -> 4
A32: =_xlfn.XLOOKUP(B32,'2023 Draft'!$C$3:$C$162,'2023 Draft'!$A$3:$A$162) -> 7 | B32: Gabe Davis | C32: WR | D32: Joe Murray | F32: 1 of 3 | G32: 2 of 3 | H32: 3 of 3 | J32: =IF(A32="FA",9,A32-1) -> 6
A33: =_xlfn.XLOOKUP(B33,'2023 Draft'!$C$3:$C$162,'2023 Draft'!$A$3:$A$162) -> 9 | B33: Tua Tagovailoa | C33: QB | D33: Joe Murray | F33: 1 of 3 | G33: 2 of 3 | H33: 3 of 3 | J33: =IF(A33="FA",9,A33-1) -> 8
A34: FA | B34: Jakobi Meyers | C34: WR | D34: Joe Murray | F34: 1 of 3 | G34: 2 of 3 | H34: 3 of 3 | J34: =IF(A34="FA",9,A34-1) -> 9
A35: FA | B35: Gus Edwards | C35: RB | D35: Joe Murray | F35: 1 of 3 | G35: 2 of 3 | H35: 3 of 3 | J35: =IF(A35="FA",9,A35-1) -> 9
A36: FA | B36: Demarcus Robinson | C36: WR | D36: Joe Murray | F36: 1 of 3 | G36: 2 of 3 | H36: 3 of 3 | J36: =IF(A36="FA",9,A36-1) -> 9
A37: =_xlfn.XLOOKUP(B37,'2023 Draft'!$C$3:$C$162,'2023 Draft'!$A$3:$A$162) -> 8 | B37: TJ Hockenson | C37: TE | D37: Joe Murray | F37: 2 of 3 | G37: 3 of 3 | H37: N/A | J37: =IF(A37="FA",9,A37-1) -> 7
A39: FA | B39: Matthew Stafford | C39: QB | D39: Scott Johnston | F39: 1 of 3 | G39: 2 of 3 | H39: 3 of 3 | J39: =IF(A39="FA",9,A39-1) -> 9
A40: =_xlfn.XLOOKUP(B40,'2023 Draft'!$C$3:$C$162,'2023 Draft'!$A$3:$A$162) -> 12 | B40: Chuba Hubbard | C40: RB | D40: Scott Johnston | F40: 1 of 3 | G40: 2 of 3 | H40: 3 of 3 | J40: =IF(A40="FA",9,A40-1) -> 11
A41: FA | B41: Ezekiel Elliott | C41: RB | D41: Scott Johnston | F41: 1 of 3 | G41: 2 of 3 | H41: 3 of 3 | J41: =IF(A41="FA",9,A41-1) -> 9
A42: =_xlfn.XLOOKUP(B42,'2023 Draft'!$C$3:$C$162,'2023 Draft'!$A$3:$A$162) -> 7 | B42: Brandon Aiyuk | C42: WR | D42: Scott Johnston | F42: 1 of 3 | G42: 2 of 3 | H42: 3 of 3 | J42: =IF(A42="FA",9,A42-1) -> 6
...

Sheet 2023 Draft
A2: Round | B2: Pick | C2: Player | D2: Position | E2: Team | F2: League Member
A3: 1 | B3: 1 | C3: Christian McCaffrey | D3: RB | E3: SF | F3: Stefan
A4: 1 | B4: 2 | C4: Tyreek Hill | D4: WR | E4: MIA | F4: Greg
A5: 1 | B5: 3 | C5: Austin Ekeler | D5: RB | E5: LAC | F5: Josh
A6: 1 | B6: 4 | C6: Travis Kelce | D6: TE | E6: KC | F6: Scott
A7: 1 | B7: 5 | C7: Stefon Diggs | D7: WR | E7: BUF | F7: Witte
A8: 1 | B8: 6 | C8: Bijan Robinson | D8: RB | E8: ATL | F8: Zach
A9: 1 | B9: 7 | C9: Nick Chubb | D9: RB | E9: CLE | F9: Elbe
A10: 1 | B10: 8 | C10: CeeDee Lamb | D10: WR | E10: DAL | F10: Kyle
A11: 1 | B11: 9 | C11: AJ Brown | D11: WR | E11: PHI | F11: Colin
A12: 1 | B12: 10 | C12: Cooper Kupp | D12: WR | E12: LAR | F12: Joe
A13: 2 | B13: 11 | C13: Saquon Barkley | D13: RB | E13: NYG | F13: Joe
A14: 2 | B14: 12 | C14: Breece Hall | D14: RB | E14: NYJ | F14: Colin
... A126: 13 | B126: 124 | C126: DeShaun Watson | D126: QB | E126: CLE | F126: Scott
A127: 13 | B127: 125 | C127: Justin Ross | F127: Stefan
A128: 13 | B128: 126 | C128: Zamir White | D128: RB | E128: LV | F128: Zach
A129: 13 | B129: 127 | C129: Jaden Reed | D129: WR | E129: GB | F129: Witte
A130: 13 | B130: 128 | C130: Chigoziem Okonkwo | D130: TE | E130: TEN | F130: Kyle
A131: 13 | B131: 129 | C131: Damien Harris | D131: RB | E131: BUF | F131: Colin
A132: 13 | B132: 130 | C132: Tyler Boyd | D132: WR | E132: CIN | F132: Joe
A133: 14 | B133: 131 | C133: Tyjae Spears | D133: RB | E133: TEN | F133: Joe
A134: 14 | B134: 132 | C134: Travis Etienne Jr. | D134: RB | E134: JAX | F134: Colin
A135: 14 | B135: 133 | C135: Cam Akers | D135: RB | E135: LAR | F135: Kyle
A136: 14 | B136: 134 | C136: Roschon Johnson | D136: RB | E136: CHI | F136: Elbe
A137: 14 | B137: 135 | C137: Ty Chandler | F137: Zach
A138: 14 | B138: 136 | C138: KJ Osborn | F138: Witte
A139: 14 | B139: 137 | C139: Puka Nacua | D139: WR | E139: LAR | F139: Scott
A140: 14 | B140: 138 | C140: JK Dobbins | D140: RB | E140: BAL | F140: Josh
A141: 14 | B141: 139 | C141: New Orleans DEF | D141: DEF | E141: NO | F141: Greg
A142: 14 | B142: 140 | C142: Parris Campbell | F142: Witte
A143: 15 | B143: 141 | C143: Dallas DEF | D143: DEF | E143: DAL | F143: Colin
A144: 15 | B144: 142 | C144: Ezekiel Elliott | D144: RB | E144: NE | F144: Witte
A145: 15 | B145: 143 | C145: Jameson Williams | D145: WR | E145: DET | F145: Josh
A146: 15 | B146: 144 | C146: Philadelphia Eagles DEF | D146: DEF | E146: PHI | F146: Scott
A147: 15 | B147: 145 | C147: Calvin Ridley | D147: WR | E147: JAX | F147: Stefan
A148: 15 | B148: 146 | C148: Kyler Murray | D148: QB | E148: ARI | F148: Zach
A149: 15 | B149: 147 | C149: Deuce Vaughn | D149: RB | E149: DAL | F149: Elbe
A150: 15 | B150: 148 | C150: Tank Dell | D150: WR | E150: HOU | F150: Kyle
A151: 15 | B151: 149 | C151: Zay Jones | D151: WR | E151: JAX | F151: Colin
A152: 15 | B152: 150 | C152: NYJ Jets DEF | D152: DEF | E152: NYJ | F152: Joe
...

Sheet Roster
B2: QB
B3: RB
B4: RB
B5: WR
B6: WR
B7: TE
B8: FLEX
B9: FLEX
B10: D/ST
B12: BENCH
B13: BENCH
B14: BENCH
... B18: BENCH

Sheet KEEPER LIST for 2022
A1: SUMMARY | H1: TERM | L1: DRAFT ROUND FOR KEEPER
A2: Pick | B2: Round | C2: Player | D2: Position | E2: League Member | H2: 2021 Status | I2: 2022 Status | J2: 2023 Status | L2: 2019 | M2: 2020 | N2: 2021 | O2: 2022
A3: =VLOOKUP(C3,'2021 Draft'!$A$2:$F$172,6,FALSE) -> 25 | B3: =VLOOKUP(C3,'2021 Draft'!$A$2:$F$172,5,FALSE) -> 3 | C3: Josh Allen | D3: QB | E3: Colin Tracy | H3: 1 of 3 | I3: 2 of 3 | J3: 3 of 3 | L3: N/A | M3: N/A | N3: =B3 -> 3 | O3: =IF(A3="FA",9,N3-1) -> 2
A4: FA | B4: FA | C4: Damien Harris | D4: RB | E4: Colin Tracy | H4: 1 of 3 | I4: 2 of 3 | J4: 3 of 3 | L4: N/A | M4: N/A | N4: FA | O4: =IF(A4="FA",9,N4-1) -> 9
A5: FA | B5: FA | C5: D'Onta Foreman | D5: RB | E5: Colin Tracy | H5: 1 of 3 | I5: 2 of 3 | J5: 3 of 3 | L5: N/A | M5: N/A | N5: FA | O5: =IF(A5="FA",9,N5-1) -> 9
A6: FA | B6: FA | C6: Cole Beasley | D6: WR | E6: Colin Tracy | H6: 1 of 3 | I6: 2 of 3 | J6: 3 of 3 | L6: N/A | M6: N/A | N6: FA | O6: =IF(A6="FA",9,N6-1) -> 9
A7: FA | B7: FA | C7: Kendrick Bourne | D7: WR | E7: Colin Tracy | H7: 1 of 3 | I7: 2 of 3 | J7: 3 of 3 | L7: N/A | M7: N/A | N7: FA | O7: =IF(A7="FA",9,N7-1) -> 9
A8: FA | B8: FA | C8: Dalton Schultz | D8: TE | E8: Colin Tracy | H8: 1 of 3 | I8: 2 of 3 | J8: 3 of 3 | L8: N/A | M8: N/A | N8: FA | O8: =IF(A8="FA",9,N8-1) -> 9
A9: =VLOOKUP(C9,'2021 Draft'!$A$2:$F$172,6,FALSE) -> 85 | B9: =VLOOKUP(C9,'2021 Draft'!$A$2:$F$172,5,FALSE) -> 9 | C9: CeeDee Lamb | D9: WR | E9: Colin Tracy | H9: 2 of 3 | I9: 3 of 3 | J9: N/A | L9: N/A | M9: 10 | N9: =B9 -> 9 | O9: =IF(A9="FA",9,N9-1) -> 8
A10: =VLOOKUP(C10,'2021 Draft'!$A$2:$F$172,6,FALSE) -> 96 | B10: =VLOOKUP(C10,'2021 Draft'!$A$2:$F$172,5,FALSE) -> 10 | C10: Melvin Gordon III | D10: RB | E10: Colin Tracy | H10: 1 of 3 | I10: 2 of 3 | J10: 3 of 3 | L10: N/A | M10: N/A | N10: =B10 -> 10 | O10: =IF(A10="FA",9,N10-1) -> 9
A11: FA | B11: FA | C11: 49ers | D11: DST | E11: Colin Tracy | H11: 1 of 3 | I11: 2 of 3 | J11: 3 of 3 | L11: N/A | M11: N/A | N11: FA | O11: =IF(A11="FA",9,N11-1) -> 9
A12: =VLOOKUP(C12,'2021 Draft'!$A$2:$F$172,6,FALSE) -> 16 | B12: =VLOOKUP(C12,'2021 Draft'!$A$2:$F$172,5,FALSE) -> 2 | C12: Robert Woods | D12: WR | E12: Colin Tracy | H12: 1 of 3 | I12: 2 of 3 | J12: 3 of 3 | L12: N/A | M12: N/A | N12: =B12 -> 2 | O12: =IF(A12="FA",9,N12-1) -> 1
A13: =VLOOKUP(C13,'2021 Draft'!$A$2:$F$172,6,FALSE) -> 116 | B13: =VLOOKUP(C13,'2021 Draft'!$A$2:$F$172,5,FALSE) -> 12 | C13: Marvin Jones Jr | D13: WR | E13: Colin Tracy | H13: 1 of 3 | I13: 2 of 3 | J13: 3 of 3 | L13: N/A | M13: N/A | N13: =B13 -> 12 | O13: =IF(A13="FA",9,N13-1) -> 11
A14: =VLOOKUP(C14,'2021 Draft'!$A$2:$F$172,6,FALSE) -> 145 | B14: =VLOOKUP(C14,'2021 Draft'!$A$2:$F$172,5,FALSE) -> 15 | C14: Jalen Hurts | D14: QB | E14: Colin Tracy | H14: 1 of 3 | I14: 2 of 3 | J14: 3 of 3 | L14: N/A | M14: N/A | N14: =B14 -> 15 | O14: =IF(A14="FA",9,N14-1) -> 14
A15: FA | B15: FA | C15: Mike Gesicki | D15: TE | E15: Colin Tracy | H15: 1 of 3 | I15: 2 of 3 | J15: 3 of 3 | L15: N/A | M15: N/A | N15: FA | O15: =IF(A15="FA",9,N15-1) -> 9
A16: FA | B16: FA | C16: Ty Johnson | D16: RB | E16: Colin Tracy | H16: 1 of 3 | I16: 2 of 3 | J16: 3 of 3 | L16: N/A | M16: N/A | N16: FA | O16: =IF(A16="FA",9,N16-1) -> 9
A17: =VLOOKUP(C17,'2021 Draft'!$A$2:$F$172,6,FALSE) -> 147 | B17: =VLOOKUP(C17,'2021 Draft'!$A$2:$F$172,5,FALSE) -> 15 | C17: Travis Etienne | D17: RB | E17: Colin Tracy | H17: 1 of 3 | I17: 2 of 3 | J17: 3 of 3 | L17: N/A | M17: N/A | N17: =B17 -> 15 | O17: =IF(A17="FA",9,N17-1) -> 14
A18: FA | B18: FA | C18: Jeff Wilson Jr. | D18: RB | E18: Colin Tracy | H18: 1 of 3 | I18: 2 of 3 | J18: 3 of 3 | L18: N/A | M18: N/A | N18: FA | O18: =IF(A18="FA",9,N18-1) -> 9
A19: =VLOOKUP(C19,'2021 Draft'!$A$2:$F$172,6,FALSE) -> 65 | B19: =VLOOKUP(C19,'2021 Draft'!$A$2:$F$172,5,FALSE) -> 7 | C19: Raheem Mostert | D19: RB | E19: Colin Tracy | H19: 1 of 3 | I19: 2 of 3 | J19: 3 of 3 | L19: N/A | M19: N/A | N19: =B19 -> 7 | O19: =IF(A19="FA",9,N19-1) -> 6
A21: =VLOOKUP(C21,'2021 Draft'!$A$2:$F$172,6,FALSE) -> 121 | B21: =VLOOKUP(C21,'2021 Draft'!$A$2:$F$172,5,FALSE) -> 13 | C21: Patrick Mahomes | D21: QB | E21: Joe Murray | H21: 2 of 3 | I21: 3 of 3 | J21: N/A | L21: 15 | M21: 14 | N21: =B21 -> 13 | O21: =IF(A21="FA",9,N21-1) -> 12
A22: =VLOOKUP(C22,'2021 Draft'!$A$2:$F$172,6,FALSE) -> 40 | B22: =VLOOKUP(C22,'2021 Draft'!$A$2:$F$172,5,FALSE) -> 4 | C22: Josh Jacobs | D22: RB | E22: Joe Murray | H22: 1 of 3 | I22: 2 of 3 | J22: 3 of 3 | L22: N/A | M22: N/A | N22: =B22 -> 4 | O22: =IF(A22="FA",9,N22-1) -> 3
A23: FA | B23: FA | C23: Rex Burkhead | D23: RB | E23: Joe Murray | H23: 1 of 3 | I23: 2 of 3 | J23: 3 of 3 | L23: N/A | M23: N/A | N23: FA | O23: =IF(A23="FA",9,N23-1) -> 9
A24: =VLOOKUP(C24,'2021 Draft'!$A$2:$F$172,6,FALSE) -> 21 | B24: =VLOOKUP(C24,'2021 Draft'!$A$2:$F$172,5,FALSE) -> 3 | C24: Tyler Lockett | D24: WR | E24: Joe Murray | H24: 1 of 3 | I24: 2 of 3 | J24: 3 of 3 | L24: N/A | M24: N/A | N24: =B24 -> 3 | O24: =IF(A24="FA",9,N24-1) -> 2
A25: =VLOOKUP(C25,'2021 Draft'!$A$2:$F$172,6,FALSE) -> 120 | B25: =VLOOKUP(C25,'2021 Draft'!$A$2:$F$172,5,FALSE) -> 12 | C25: Justin Jefferson | D25: WR | E25: Joe Murray | H25: 2 of 3 | I25: 3 of 3 | J25: N/A | L25: N/A | M25: 13 | N25: =B25 -> 12 | O25: =IF(A25="FA",9,N25-1) -> 11
A26: FA | B26: FA | C26: Dawson Knox | D26: TE | E26: Joe Murray | H26: 2 of 3 | I26: 3 of 3 | J26: N/A | L26: N/A | M26: N/A | N26: FA | O26: =IF(A26="FA",9,N26-1) -> 9
A27: FA | B27: FA | C27: Russell Gage | D27: WR | E27: Joe Murray | H27: 1 of 3 | I27: 2 of 3 | J27: 3 of 3 | L27: N/A | M27: N/A | N27: FA | O27: =IF(A27="FA",9,N27-1) -> 9
A28: FA | B28: FA | C28: AJ Green | D28: WR | E28: Joe Murray | H28: 1 of 3 | I28: 2 of 3 | J28: 3 of 3 | L28: N/A | M28: N/A | N28: FA | O28: =IF(A28="FA",9,N28-1) -> 9
A29: FA | B29: FA | C29: Panthers | D29: DST | E29: Joe Murray | H29: 1 of 3 | I29: 2 of 3 | J29: 3 of 3 | L29: N/A | M29: N/A | N29: FA | O29: =IF(A29="FA",9,N29-1) -> 9
A30: =VLOOKUP(C30,'2021 Draft'!$A$2:$F$172,6,FALSE) -> 41 | B30: =VLOOKUP(C30,'2021 Draft'!$A$2:$F$172,5,FALSE) -> 5 | C30: Jerry Jeudy | D30: WR | E30: Joe Murray | H30: 1 of 3 | I30: 2 of 3 | J30: 3 of 3 | L30: N/A | M30: N/A | N30: =B30 -> 5 | O30: =IF(A30="FA",9,N30-1) -> 4
A31: =VLOOKUP(C31,'2021 Draft'!$A$2:$F$172,6,FALSE) -> 61 | B31: =VLOOKUP(C31,'2021 Draft'!$A$2:$F$172,5,FALSE) -> 7 | C31: Courtland Sutton | D31: WR | E31: Joe Murray | H31: 1 of 3 | I31: 2 of 3 | J31: 3 of 3 | L31: N/A | M31: N/A | N31: =B31 -> 7 | O31: =IF(A31="FA",9,N31-1) -> 6
A32: FA | B32: FA | C32: Hunter Henry | D32: TE | E32: Joe Murray | H32: 1 of 3 | I32: 2 of 3 | J32: 3 of 3 | L32: N/A | M32: N/A | N32: FA | O32: =IF(A32="FA",9,N32-1) -> 9
A33: FA | B33: FA | C33: Emmanuel Sanders | D33: WR | E33: Joe Murray | H33: 1 of 3 | I33: 2 of 3 | J33: 3 of 3 | L33: N/A | M33: N/A | N33: FA | O33: =IF(A33="FA",9,N33-1) -> 9
A34: FA | B34: FA | C34: Mike Davis | D34: RB | E34: Joe Murray | H34: 1 of 3 | I34: 2 of 3 | J34: 3 of 3 | L34: N/A | M34: N/A | N34: FA | O34: =IF(A34="FA",9,N34-1) -> 9
A35: FA | B35: FA | C35: Robby Anderson | D35: WR | E35: Joe Murray | H35: 1 of 3 | I35: 2 of 3 | J35: 3 of 3 | L35: N/A | M35: N/A | N35: FA | O35: =IF(A35="FA",9,N35-1) -> 9
A36: FA | B36: FA | C36: Tyler Higbee | D36: TE | E36: Joe Murray | H36: 1 of 3 | I36: 2 of 3 | J36: 3 of 3 | L36: N/A | M36: N/A | N36: FA | O36: =IF(A36="FA",9,N36-1) -> 9
A37: =VLOOKUP(C37,'2021 Draft'!$A$2:$F$172,6,FALSE) -> 1 | B37: =VLOOKUP(C37,'2021 Draft'!$A$2:$F$172,5,FALSE) -> 1 | C37: Christian McCaffrey | D37: RB | E37: Joe Murray | H37: 1 of 3 | I37: 2 of 3 | J37: 3 of 3 | L37: N/A | M37: N/A | N37: =B37 -> 1 | O37: =IF(A37="FA",9,N37-1) -> 0
A39: =VLOOKUP(C39,'2021 Draft'!$A$2:$F$172,6,FALSE) -> 143 | B39: =VLOOKUP(C39,'2021 Draft'!$A$2:$F$172,5,FALSE) -> 15 | C39: Trevor Lawrence | D39: QB | E39: Scott Johnston | H39: 1 of 3 | I39: 2 of 3 | J39: 3 of 3 | L39: N/A | M39: N/A | N39: =B39 -> 15 | O39: =IF(A39="FA",9,N39-1) -> 14
A40: =VLOOKUP(C40,'2021 Draft'!$A$2:$F$172,6,FALSE) -> 18 | B40: =VLOOKUP(C40,'2021 Draft'!$A$2:$F$172,5,FALSE) -> 2 | C40: David Montgomery | D40: RB | E40: Scott Johnston | H40: 1 of 3 | I40: 2 of 3 | J40: 3 of 3 | L40: N/A | M40: N/A | N40: =B40 -> 2 | O40: =IF(A40="FA",9,N40-1) -> 1
A41: =VLOOKUP(C41,'2021 Draft'!$A$2:$F$172,6,FALSE) -> 83 | B41: =VLOOKUP(C41,'2021 Draft'!$A$2:$F$172,5,FALSE) -> 9 | C41: Aaron Jones | D41: RB | E41: Scott Johnston | H41: 2 of 3 | I41: 3 of 3 | J41: N/A | L41: 11 | M41: 10 | N41: =B41 -> 9 | O41: =IF(A41="FA",9,N41-1) -> 8
A42: =VLOOKUP(C42,'2021 Draft'!$A$2:$F$172,6,FALSE) -> 3 | B42: =VLOOKUP(C42,'2021 Draft'!$A$2:$F$172,5,FALSE) -> 1 | C42: Davante Adams | D42: WR | E42: Scott Johnston | H42: 1 of 3 | I42: 2 of 3 | J42: 3 of 3 | L42: N/A | M42: N/A | N42: =B42 -> 1 | O42: =IF(A42="FA",9,N42-1) -> 0
...

Sheet 2021 Draft
A1: Player | B1: Position | C1: Team | D1: League Member | E1: Round | F1: Pick
A2: Christian McCaffrey | B2: RB | C2: CAR | D2: Joe | E2: 1 | F2: 1
A3: Dalvin Cook | B3: RB | C3: MIN | D3: Josh | E3: 1 | F3: 2
A4: Davante Adams | B4: WR | C4: GB | D4: Scott | E4: 1 | F4: 3
A5: Ezekiel Elliott | B5: RB | C5: DAL | D5: Elbe | E5: 1 | F5: 4
A6: Saquon Barkley | B6: RB | C6: NYG | D6: Colin | E6: 1 | F6: 5
A7: Tyreek Hill | B7: WR | C7: KC | D7: Stefan | E7: 1 | F7: 6
A8: Najee Harris | B8: RB | C8: PIT | D8: Zach | E8: 1 | F8: 7
A9: DeAndre Hopkins | B9: WR | C9: ARI | D9: Kyle | E9: 1 | F9: 8
A10: Terry McLaurin | B10: WR | C10: WA | D10: Witte | E10: 1 | F10: 9
A11: Joe Mixon | B11: RB | C11: CIN | D11: Greg | E11: 1 | F11: 10
A12: Travis Kelce | B12: TE | C12: KC | D12: Greg | E12: 2 | F12: 11
A13: Allen Robinson | B13: WR | C13: CHI | D13: Witte | E13: 2 | F13: 12
... A104: Melvin Gordon III | B104: RB | C104: DEN | D104: Colin | E104: 10 | F104: 96
A105: Michael Gallup | B105: WR | D105: Elbe | E105: 10 | F105: 97
A106: Brandon Aiyuk | B106: WR | C106: SF | D106: Scott | E106: 10 | F106: 98
A107: Michael Pittman Jr | B107: WR | C107: IND | D107: Josh | E107: 10 | F107: 99
A108: Kenyan Drake | B108: RB | C108: LAV | D108: Joe | E108: 10 | F108: 100
A109: Devin Singletary | B109: RB | C109: BUF | D109: Joe | E109: 11 | F109: 101
A110: James Conner | B110: RB | C110: ARI | D110: Josh | E110: 11 | F110: 102
A111: Tyler Higbee | B111: TE | C111: LAR | D111: Scott | E111: 11 | F111: 103
A112: Leonard Fournette | B112: RB | C112: JAX | D112: Elbe | E112: 11 | F112: 104
A113: Dallas Goedert | B113: TE | C113: PHI | D113: Colin | E113: 11 | F113: 105
A114: Darnell Mooney | B114: WR | C114: CHI | D114: Stefan | E114: 11 | F114: 106
A115: Jamaal Williams | B115: RB | C115: DET | D115: Zach | E115: 11 | F115: 107
A116: Phillip Lindsay | B116: RB | C116: HOU | D116: Kyle | E116: 11 | F116: 108
A117: Jakobi Meyers | B117: WR | C117: NE | D117: Witte | E117: 11 | F117: 109
... A172: Blake Jarwin | B172: TE | C172: DAL | D172: Joe | E172: 16 | F172: 160

Sheet KEEPER LIST for 2021
A1: SUMMARY | H1: TERM | L1: DRAFT ROUND FOR KEEPER
A2: Pick | B2: Round | C2: Player | D2: Position | E2: League Member | H2: 2020 Status | I2: 2021 Status | J2: 2022 Status | L2: 2018 | M2: 2019 | N2: 2020 | O2: 2021
A3: =VLOOKUP(C3,'2020 Draft'!$C$3:$G$161,5,FALSE) -> 70 | B3: =VLOOKUP(C3,'2020 Draft'!$C$2:$H$161,6,FALSE) -> 7 | C3: Josh Allen | D3: QB | E3: Colin Tracy | H3: 1 of 3 | I3: 2 of 3 | J3: 3 of 3 | L3: N/A | M3: N/A | N3: =B3 -> 7 | O3: =IF(A3="FA",9,N3-1) -> 6
A4: =VLOOKUP(C4,'2020 Draft'!$C$3:$G$161,5,FALSE) -> 50 | B4: =VLOOKUP(C4,'2020 Draft'!$C$2:$H$161,6,FALSE) -> 5 | C4: Austin Ekeler | D4: RB | E4: Colin Tracy | H4: 2 of 3 | I4: 3 of 3 | J4: N/A | L4: N/A | M4: 6 | N4: =B4 -> 5 | O4: =IF(A4="FA",9,N4-1) -> 4
A5: FA | B5: FA | C5: Gus Edwards | D5: RB | E5: Colin Tracy | H5: 1 of 3 | I5: 2 of 3 | J5: 3 of 3 | L5: N/A | M5: N/A | N5: =B5 -> FA | O5: =IF(A5="FA",9,N5-1) -> 9
A6: =VLOOKUP(C6,'2020 Draft'!$C$3:$G$161,5,FALSE) -> 31 | B6: =VLOOKUP(C6,'2020 Draft'!$C$2:$H$161,6,FALSE) -> 4 | C6: D.J. Chark | D6: WR | E6: Colin Tracy | H6: 1 of 3 | I6: 2 of 3 | J6: 3 of 3 | L6: N/A | M6: N/A | N6: =B6 -> 4 | O6: =IF(A6="FA",9,N6-1) -> 3
A7: =VLOOKUP(C7,'2020 Draft'!$C$3:$G$161,5,FALSE) -> 51 | B7: =VLOOKUP(C7,'2020 Draft'!$C$2:$H$161,6,FALSE) -> 6 | C7: Adam Thielen | D7: WR | E7: Colin Tracy | H7: 3 of 3 | I7: N/A | J7: N/A | L7: 8 | M7: 7 | N7: =B7 -> 6 | O7: N/A
A8: =VLOOKUP(C8,'2020 Draft'!$C$3:$G$161,5,FALSE) -> 71 | B8: =VLOOKUP(C8,'2020 Draft'!$C$2:$H$161,6,FALSE) -> 8 | C8: Jamison Crowder | D8: WR | E8: Colin Tracy | H8: 1 of 3 | I8: 2 of 3 | J8: 3 of 3 | L8: N/A | M8: N/A | N8: =B8 -> 8 | O8: =IF(A8="FA",9,N8-1) -> 7
A9: =VLOOKUP(C9,'2020 Draft'!$C$3:$G$161,5,FALSE) -> 91 | B9: =VLOOKUP(C9,'2020 Draft'!$C$2:$H$161,6,FALSE) -> 10 | C9: CeeDee Lamb | D9: WR | E9: Colin Tracy | H9: 1 of 3 | I9: 2 of 3 | J9: 3 of 3 | L9: N/A | M9: N/A | N9: =B9 -> 10 | O9: =IF(A9="FA",9,N9-1) -> 9
A10: FA | B10: FA | C10: Dolphins | D10: DST | E10: Colin Tracy | H10: 1 of 3 | I10: 2 of 3 | J10: 3 of 3 | L10: N/A | M10: N/A | N10: =B10 -> FA | O10: =IF(A10="FA",9,N10-1) -> 9
A11: =VLOOKUP(C11,'2020 Draft'!$C$3:$G$161,5,FALSE) -> 11 | B11: =VLOOKUP(C11,'2020 Draft'!$C$2:$H$161,6,FALSE) -> 2 | C11: Julio Jones | D11: WR | E11: Colin Tracy | H11: 1 of 3 | I11: 2 of 3 | J11: 3 of 3 | L11: N/A | M11: N/A | N11: =B11 -> 2 | O11: =IF(A11="FA",9,N11-1) -> 1
A12: =VLOOKUP(C12,'2020 Draft'!$C$3:$G$161,5,FALSE) -> 131 | B12: =VLOOKUP(C12,'2020 Draft'!$C$2:$H$161,6,FALSE) -> 14 | C12: Hunter Henry | D12: TE | E12: Colin Tracy | H12: 1 of 3 | I12: 2 of 3 | J12: 3 of 3 | L12: N/A | M12: N/A | N12: =B12 -> 14 | O12: =IF(A12="FA",9,N12-1) -> 13
A13: =VLOOKUP(C13,'2020 Draft'!$C$3:$G$161,5,FALSE) -> 150 | B13: =VLOOKUP(C13,'2020 Draft'!$C$2:$H$161,6,FALSE) -> 15 | C13: Tom Brady | D13: QB | E13: Colin Tracy | H13: 1 of 3 | I13: 2 of 3 | J13: 3 of 3 | L13: N/A | M13: N/A | N13: =B13 -> 15 | O13: =IF(A13="FA",9,N13-1) -> 14
A14: FA | B14: FA | C14: James Robinson | D14: RB | E14: Colin Tracy | H14: 1 of 3 | I14: 2 of 3 | J14: 3 of 3 | L14: N/A | M14: N/A | N14: =B14 -> FA | O14: =IF(A14="FA",9,N14-1) -> 9
A15: FA | B15: FA | C15: Nelson Agholor | D15: WR | E15: Colin Tracy | H15: 1 of 3 | I15: 2 of 3 | J15: 3 of 3 | L15: N/A | M15: N/A | N15: =B15 -> FA | O15: =IF(A15="FA",9,N15-1) -> 9
A16: FA | B16: FA | C16: Deebo Samuel | D16: WR | E16: Colin Tracy | H16: 1 of 3 | I16: 2 of 3 | J16: 3 of 3 | L16: N/A | M16: N/A | N16: =B16 -> FA | O16: =IF(A16="FA",9,N16-1) -> 9
A17: FA | B17: FA | C17: Football Team | D17: DST | E17: Colin Tracy | H17: 1 of 3 | I17: 2 of 3 | J17: 3 of 3 | L17: N/A | M17: N/A | N17: =B17 -> FA | O17: =IF(A17="FA",9,N17-1) -> 9
A18: FA | B18: FA | C18: DeAndre Washington | D18: RB | E18: Colin Tracy | H18: 1 of 3 | I18: 2 of 3 | J18: 3 of 3 | L18: N/A | M18: N/A | N18: =B18 -> FA | O18: =IF(A18="FA",9,N18-1) -> 9
A19: =VLOOKUP(C19,'2020 Draft'!$C$3:$G$161,5,FALSE) -> 10 | B19: =VLOOKUP(C19,'2020 Draft'!$C$2:$H$161,6,FALSE) -> 1 | C19: Joe Mixon | D19: RB | E19: Colin Tracy | H19: 1 of 3 | I19: 2 of 3 | J19: 3 of 3 | L19: N/A | M19: N/A | N19: =B19 -> 1 | O19: =IF(A19="FA",9,N19-1) -> 0
A21: =VLOOKUP(C21,'2020 Draft'!$C$3:$G$161,5,FALSE) -> 135 | B21: =VLOOKUP(C21,'2020 Draft'!$C$2:$H$161,6,FALSE) -> 14 | C21: Patrick Mahomes | D21: QB | E21: Joe Murray | H21: 1 of 3 | I21: 2 of 3 | J21: 3 of 3 | L21: N/A | M21: 15 | N21: =B21 -> 14 | O21: =IF(A21="FA",9,N21-1) -> 13
A22: FA | B22: FA | C22: Malcolm Brown | D22: RB | E22: Joe Murray | H22: 1 of 3 | I22: 2 of 3 | J22: 3 of 3 | L22: N/A | M22: N/A | N22: =B22 -> FA | O22: =IF(A22="FA",9,N22-1) -> 9
A23: =VLOOKUP(C23,'2020 Draft'!$C$3:$G$161,5,FALSE) -> 54 | B23: =VLOOKUP(C23,'2020 Draft'!$C$2:$H$161,6,FALSE) -> 6 | C23: David Montgomery | D23: RB | E23: Joe Murray | H23: 1 of 3 | I23: 2 of 3 | J23: 3 of 3 | L23: N/A | M23: N/A | N23: =B23 -> 6 | O23: =IF(A23="FA",9,N23-1) -> 5
A24: =VLOOKUP(C24,'2020 Draft'!$C$3:$G$161,5,FALSE) -> 28 | B24: =VLOOKUP(C24,'2020 Draft'!$C$2:$H$161,6,FALSE) -> 3 | C24: Tyler Lockett | D24: WR | E24: Joe Murray | H24: 1 of 3 | I24: 2 of 3 | J24: 3 of 3 | L24: N/A | M24: N/A | N24: =B24 -> 3 | O24: =IF(A24="FA",9,N24-1) -> 2
A25: =VLOOKUP(C25,'2020 Draft'!$C$3:$G$161,5,FALSE) -> 124 | B25: =VLOOKUP(C25,'2020 Draft'!$C$2:$H$161,6,FALSE) -> 13 | C25: Justin Jefferson | D25: WR | E25: Joe Murray | H25: 1 of 3 | I25: 2 of 3 | J25: 3 of 3 | L25: N/A | M25: N/A | N25: =B25 -> 13 | O25: =IF(A25="FA",9,N25-1) -> 12
A26: =VLOOKUP(C26,'2020 Draft'!$C$3:$G$161,5,FALSE) -> 82 | B26: =VLOOKUP(C26,'2020 Draft'!$C$2:$H$161,6,FALSE) -> 9 | C26: Darren Waller | D26: TE | E26: Joe Murray | H26: 2 of 3 | I26: 3 of 3 | J26: N/A | L26: N/A | M26: N/A | N26: =B26 -> 9 | O26: =IF(A26="FA",9,N26-1) -> 8
A27: FA | B27: FA | C27: Curtis Samuel | D27: WR | E27: Joe Murray | H27: 1 of 3 | I27: 2 of 3 | J27: 3 of 3 | L27: N/A | M27: N/A | N27: =B27 -> FA | O27: =IF(A27="FA",9,N27-1) -> 9
A28: FA | B28: FA | C28: Tim Patrick | D28: WR | E28: Joe Murray | H28: 1 of 3 | I28: 2 of 3 | J28: 3 of 3 | L28: N/A | M28: N/A | N28: =B28 -> FA | O28: =IF(A28="FA",9,N28-1) -> 9
A29: =VLOOKUP(C29,'2020 Draft'!$C$3:$G$161,5,FALSE) -> 122 | B29: =VLOOKUP(C29,'2020 Draft'!$C$2:$H$161,6,FALSE) -> 13 | C29: Ravens | D29: DST | E29: Joe Murray | H29: 1 of 3 | I29: 2 of 3 | J29: 3 of 3 | L29: N/A | M29: N/A | N29: =B29 -> 13 | O29: =IF(A29="FA",9,N29-1) -> 12
A30: =VLOOKUP(C30,'2020 Draft'!$C$3:$G$161,5,FALSE) -> 39 | B30: =VLOOKUP(C30,'2020 Draft'!$C$2:$H$161,6,FALSE) -> 4 | C30: T.Y. Hilton | D30: WR | E30: Joe Murray | H30: 1 of 3 | I30: 2 of 3 | J30: 3 of 3 | L30: N/A | M30: N/A | N30: =B30 -> 4 | O30: =IF(A30="FA",9,N30-1) -> 3
A31: =VLOOKUP(C31,'2020 Draft'!$C$3:$G$161,5,FALSE) -> 42 | B31: =VLOOKUP(C31,'2020 Draft'!$C$2:$H$161,6,FALSE) -> 5 | C31: Devin Singletary | D31: RB | E31: Joe Murray | H31: 1 of 3 | I31: 2 of 3 | J31: 3 of 3 | L31: N/A | M31: N/A | N31: =B31 -> 5 | O31: =IF(A31="FA",9,N31-1) -> 4
A32: FA | B32: FA | C32: Greg Ward | D32: WR | E32: Joe Murray | H32: 1 of 3 | I32: 2 of 3 | J32: 3 of 3 | L32: N/A | M32: N/A | N32: =B32 -> FA | O32: =IF(A32="FA",9,N32-1) -> 9
A33: FA | B33: FA | C33: Jimmy Graham | D33: TE | E33: Joe Murray | H33: 1 of 3 | I33: 2 of 3 | J33: 3 of 3 | L33: N/A | M33: N/A | N33: =B33 -> FA | O33: =IF(A33="FA",9,N33-1) -> 9
A34: FA | B34: FA | C34: Cordarrelle Patterson | D34: WR,RB | E34: Joe Murray | H34: 1 of 3 | I34: 2 of 3 | J34: 3 of 3 | L34: N/A | M34: N/A | N34: =B34 -> FA | O34: =IF(A34="FA",9,N34-1) -> 9
A35: FA | B35: FA | C35: Keelan Cole Sr. | D35: WR | E35: Joe Murray | H35: 1 of 3 | I35: 2 of 3 | J35: 3 of 3 | L35: N/A | M35: N/A | N35: =B35 -> FA | O35: =IF(A35="FA",9,N35-1) -> 9
A36: FA | B36: FA | C36: Robert Tonyan | D36: TE | E36: Joe Murray | H36: 1 of 3 | I36: 2 of 3 | J36: 3 of 3 | L36: N/A | M36: N/A | N36: =B36 -> FA | O36: =IF(A36="FA",9,N36-1) -> 9
A37: FA | B37: FA | C37: Rex Burkhead | D37: RB | E37: Joe Murray | H37: 1 of 3 | I37: 2 of 3 | J37: 3 of 3 | L37: N/A | M37: N/A | N37: =B37 -> FA | O37: =IF(A37="FA",9,N37-1) -> 9
A39: FA | B39: FA | C39: Cam Newton | D39: QB | E39: Scott Johnston | H39: 1 of 3 | I39: 2 of 3 | J39: 3 of 3 | L39: N/A | M39: N/A | N39: =B39 -> FA | O39: =IF(A39="FA",9,N39-1) -> 9
A40: =VLOOKUP(C40,'2020 Draft'!$C$3:$G$161,5,FALSE) -> 63 | B40: =VLOOKUP(C40,'2020 Draft'!$C$2:$H$161,6,FALSE) -> 7 | C40: Kareem Hunt | D40: RB | E40: Scott Johnston | H40: 1 of 3 | I40: 2 of 3 | J40: 3 of 3 | L40: N/A | M40: N/A | N40: =B40 -> 7 | O40: =IF(A40="FA",9,N40-1) -> 6
A41: =VLOOKUP(C41,'2020 Draft'!$C$3:$G$161,5,FALSE) -> 92 | B41: =VLOOKUP(C41,'2020 Draft'!$C$2:$H$161,6,FALSE) -> 10 | C41: Aaron Jones | D41: RB | E41: Scott Johnston | H41: 1 of 3 | I41: 2 of 3 | J41: 3 of 3 | L41: N/A | M41: N/A | N41: =B41 -> 10 | O41: =IF(A41="FA",9,N41-1) -> 9
A42: =VLOOKUP(C42,'2020 Draft'!$C$3:$G$161,5,FALSE) -> 18 | B42: =VLOOKUP(C42,'2020 Draft'!$C$2:$H$161,6,FALSE) -> 2 | C42: JuJu Smith-Schuster | D42: WR | E42: Scott Johnston | H42: 1 of 3 | I42: 2 of 3 | J42: 3 of 3 | L42: N/A | M42: N/A | N42: =B42 -> 2 | O42: =IF(A42="FA",9,N42-1) -> 1
...

Sheet KEEPER LIST for 2020
A1: SUMMARY | I1: TERM | M1: DRAFT ROUND FOR KEEPER
A2: Pick | B2: Round | C2: Player | D2: Position | E2: Team | F2: League Member | I2: 2019 Status | J2: 2020 Status | K2: 2021 Status | M2: 2018 | N2: 2019 | O2: 2020 | P2: 2021
A3: =VLOOKUP(C3,'2019 Draft by Round'!$C$2:$G$161,5,FALSE) -> 45 | B3: =VLOOKUP(C3,'2019 Draft by Round'!$C$2:$H$161,6,FALSE) -> 5 | C3: Deshaun Watson | D3: QB | E3: HOU | F3: Colin Tracy | I3: 1 of 3 | J3: 2 of 3 | K3: 3 of 3 | M3: 14 | N3: =B3 -> 5 | O3: =N3-1 -> 4 | P3: =O3-1 -> 3
A4: =VLOOKUP(C4,'2019 Draft by Round'!$C$2:$G$161,5,FALSE) -> 36 | B4: =VLOOKUP(C4,'2019 Draft by Round'!$C$2:$H$161,6,FALSE) -> 4 | C4: Mark Ingram II | D4: RB | E4: BAL | F4: Colin Tracy | I4: 1 of 3 | J4: 2 of 3 | K4: 3 of 3 | M4: N/A | N4: =B4 -> 4 | O4: =N4-1 -> 3 | P4: =O4-1 -> 2
A5: =VLOOKUP(C5,'2019 Draft by Round'!$C$2:$G$161,5,FALSE) -> 69 | B5: =VLOOKUP(C5,'2019 Draft by Round'!$C$2:$H$161,6,FALSE) -> 7 | C5: Austin Ekeler | D5: RB | E5: LAC | F5: Colin Tracy | I5: 1 of 3 | J5: 2 of 3 | K5: 3 of 3 | M5: N/A | N5: =B5 -> 7 | O5: =N5-1 -> 6 | P5: =O5-1 -> 5
A6: =VLOOKUP(C6,'2019 Draft by Round'!$C$2:$G$161,5,FALSE) -> 5 | B6: =VLOOKUP(C6,'2019 Draft by Round'!$C$2:$H$161,6,FALSE) -> 1 | C6: Davante Adams | D6: WR | E6: GB | F6: Colin Tracy | I6: 1 of 3 | J6: 2 of 3 | K6: 3 of 3 | M6: 9 | N6: =B6 -> 1 | O6: N/A | P6: N/A
A7: =VLOOKUP(C7,'2019 Draft by Round'!$C$2:$G$161,5,FALSE) -> 65 | B7: =VLOOKUP(C7,'2019 Draft by Round'!$C$2:$H$161,6,FALSE) -> 7 | C7: Adam Thielen | D7: WR | E7: MIN | F7: Colin Tracy | I7: 2 of 3 | J7: 3 of 3 | K7: N/A | M7: N/A | N7: =B7 -> 7 | O7: =N7-1 -> 6 | P7: N/A
A8: =VLOOKUP(C8,'2019 Draft by Round'!$C$2:$G$161,5,FALSE) -> 25 | B8: =VLOOKUP(C8,'2019 Draft by Round'!$C$2:$H$161,6,FALSE) -> 3 | C8: Zach Ertz | D8: TE | E8: PHI | F8: Colin Tracy | I8: 1 of 3 | J8: 2 of 3 | K8: 3 of 3 | M8: N/A | N8: =B8 -> 3 | O8: =N8-1 -> 2 | P8: =O8-1 -> 1
A9: =VLOOKUP(C9,'2019 Draft by Round'!$C$2:$G$161,5,FALSE) -> 16 | B9: =VLOOKUP(C9,'2019 Draft by Round'!$C$2:$H$161,6,FALSE) -> 2 | C9: Melvin Gordon | D9: WR | E9: LAC | F9: Colin Tracy | I9: 1 of 3 | J9: 2 of 3 | K9: 3 of 3 | M9: N/A | N9: =B9 -> 2 | O9: =N9-1 -> 1 | P9: N/A
A10: =VLOOKUP(C10,'2019 Draft by Round'!$C$2:$G$161,5,FALSE) -> 85 | B10: =VLOOKUP(C10,'2019 Draft by Round'!$C$2:$H$161,6,FALSE) -> 9 | C10: Robert Woods | D10: WR | E10: LAR | F10: Colin Tracy | I10: 2 of 3 | J10: 3 of 3 | K10: N/A | M10: N/A | N10: =B10 -> 9 | O10: =N10-1 -> 8 | P10: N/A
A11: =VLOOKUP(C11,'2019 Draft by Round'!$C$2:$G$161,5,FALSE) -> #N/A | B11: =VLOOKUP(C11,'2019 Draft by Round'!$C$2:$H$161,6,FALSE) -> #N/A | C11: NY Jets | D11: D/ST | E11: NYJ | F11: Colin Tracy | I11: 1 of 3 | J11: 2 of 3 | K11: 3 of 3 | M11: N/A | N11: N/A | O11: 9 | P11: =O11-1 -> 8
A12: =VLOOKUP(C12,'2019 Draft by Round'!$C$2:$G$161,5,FALSE) -> 76 | B12: =VLOOKUP(C12,'2019 Draft by Round'!$C$2:$H$161,6,FALSE) -> 8 | C12: Latavius Murray | D12: RB | E12: NO | F12: Colin Tracy | I12: 1 of 3 | J12: 2 of 3 | K12: 3 of 3 | M12: N/A | N12: =B12 -> 8 | O12: =N12-1 -> 7 | P12: =O12-1 -> 6
A13: =VLOOKUP(C13,'2019 Draft by Round'!$C$2:$G$161,5,FALSE) -> 116 | B13: =VLOOKUP(C13,'2019 Draft by Round'!$C$2:$H$161,6,FALSE) -> 12 | C13: Emmanuel Sanders | D13: WR | E13: SF | F13: Colin Tracy | I13: 1 of 3 | J13: 2 of 3 | K13: 3 of 3 | M13: N/A | N13: =B13 -> 12 | O13: =N13-1 -> 11 | P13: =O13-1 -> 10
A14: =VLOOKUP(C14,'2019 Draft by Round'!$C$2:$G$161,5,FALSE) -> #N/A | B14: =VLOOKUP(C14,'2019 Draft by Round'!$C$2:$H$161,6,FALSE) -> #N/A | C14: Bo Scarbrough | D14: RB | E14: DET | F14: Colin Tracy | I14: 1 of 3 | J14: 2 of 3 | K14: 3 of 3 | M14: N/A | N14: N/A | O14: 9 | P14: =O14-1 -> 8
A15: =VLOOKUP(C15,'2019 Draft by Round'!$C$2:$G$161,5,FALSE) -> #N/A | B15: =VLOOKUP(C15,'2019 Draft by Round'!$C$2:$H$161,6,FALSE) -> #N/A | C15: Sterling Shepard | D15: WR | E15: CHI | F15: Colin Tracy | I15: 1 of 3 | J15: 2 of 3 | K15: 3 of 3 | M15: N/A | N15: N/A | O15: 9 | P15: =O15-1 -> 8
A16: =VLOOKUP(C16,'2019 Draft by Round'!$C$2:$G$161,5,FALSE) -> 109 | B16: =VLOOKUP(C16,'2019 Draft by Round'!$C$2:$H$161,6,FALSE) -> 11 | C16: Anthony Miller | D16: D/ST | E16: HOU | F16: Colin Tracy | I16: 1 of 3 | J16: 2 of 3 | K16: 3 of 3 | M16: N/A | N16: N/A | O16: 9 | P16: =O16-1 -> 8
A17: =VLOOKUP(C17,'2019 Draft by Round'!$C$2:$G$161,5,FALSE) -> #N/A | B17: =VLOOKUP(C17,'2019 Draft by Round'!$C$2:$H$161,6,FALSE) -> #N/A | C17: LA Rams | D17: D/ST | E17: LAR | F17: Colin Tracy | I17: 1 of 3 | J17: 2 of 3 | K17: 3 of 3 | M17: N/A | N17: N/A | O17: 9 | P17: =O17-1 -> 8
A18: =VLOOKUP(C18,'2019 Draft by Round'!$C$2:$G$161,5,FALSE) -> #N/A | B18: =VLOOKUP(C18,'2019 Draft by Round'!$C$2:$H$161,6,FALSE) -> #N/A | C18: Patrick Laird | D18: RB | E18: MIA | F18: Colin Tracy | I18: 1 of 3 | J18: 2 of 3 | K18: 3 of 3 | M18: N/A | N18: N/A | O18: 9 | P18: =O18-1 -> 8
A20: =VLOOKUP(C20,'2019 Draft by Round'!$C$2:$G$161,5,FALSE) -> #N/A | B20: =VLOOKUP(C20,'2019 Draft by Round'!$C$2:$H$161,6,FALSE) -> #N/A | C20: Jimmy Garoppolo | D20: QB | E20: SF | F20: Joe Murray | I20: 1 of 3 | J20: 2 of 3 | K20: 3 of 3 | M20: 6 | N20: N/A | O20: 9 | P20: =O20-1 -> 8
A21: =VLOOKUP(C21,'2019 Draft by Round'!$C$2:$G$161,5,FALSE) -> 13 | B21: =VLOOKUP(C21,'2019 Draft by Round'!$C$2:$H$161,6,FALSE) -> 2 | C21: Joe Mixon | D21: RB | E21: CIN | F21: Joe Murray | I21: 1 of 3 | J21: 2 of 3 | K21: 3 of 3 | M21: 2 | N21: =B21 -> 2 | O21: =N21-1 -> 1 | P21: N/A
A22: =VLOOKUP(C22,'2019 Draft by Round'!$C$2:$G$161,5,FALSE) -> 22 | B22: =VLOOKUP(C22,'2019 Draft by Round'!$C$2:$H$161,6,FALSE) -> 3 | C22: Devonta Freeman | D22: RB | E22: ATL | F22: Joe Murray | I22: 1 of 3 | J22: 2 of 3 | K22: 3 of 3 | M22: N/A | N22: =B22 -> 3 | O22: =N22-1 -> 2 | P22: =O22-1 -> 1
A23: =VLOOKUP(C23,'2019 Draft by Round'!$C$2:$G$161,5,FALSE) -> 33 | B23: =VLOOKUP(C23,'2019 Draft by Round'!$C$2:$H$161,6,FALSE) -> 4 | C23: Tyler Boyd | D23: WR | E23: CIN | F23: Joe Murray | I23: 1 of 3 | J23: 2 of 3 | K23: 3 of 3 | M23: N/A | N23: =B23 -> 4 | O23: =N23-1 -> 3 | P23: =O23-1 -> 2
A24: =VLOOKUP(C24,'2019 Draft by Round'!$C$2:$G$161,5,FALSE) -> 93 | B24: =VLOOKUP(C24,'2019 Draft by Round'!$C$2:$H$161,6,FALSE) -> 10 | C24: Courtland Sutton | D24: WR | E24: DEN | F24: Joe Murray | I24: 1 of 3 | J24: 2 of 3 | K24: 3 of 3 | M24: N/A | N24: =B24 -> 10 | O24: =N24-1 -> 9 | P24: =O24-1 -> 8
A25: =VLOOKUP(C25,'2019 Draft by Round'!$C$2:$G$161,5,FALSE) -> #N/A | B25: =VLOOKUP(C25,'2019 Draft by Round'!$C$2:$H$161,6,FALSE) -> #N/A | C25: Darren Waller | D25: TE | E25: LAV | F25: Joe Murray | I25: 1 of 3 | J25: 2 of 3 | K25: 3 of 3 | M25: N/A | N25: N/A | O25: 9 | P25: =O25-1 -> 8
A26: =VLOOKUP(C26,'2019 Draft by Round'!$C$2:$G$161,5,FALSE) -> 53 | B26: =VLOOKUP(C26,'2019 Draft by Round'!$C$2:$H$161,6,FALSE) -> 6 | C26: Allen Robinson | D26: WR | E26: CHI | F26: Joe Murray | I26: 1 of 3 | J26: 2 of 3 | K26: 3 of 3 | M26: N/A | N26: =B26 -> 6 | O26: =N26-1 -> 5 | P26: =O26-1 -> 4
