Workbook
Name Tom: #REF!
Name Tom: #REF!

Sheet Draft Board
A1: Buy Me A Beer paypal venmo cashapp dsa coffee | D1: =IFERROR(__xludf.DUMMYFUNCTION("IF(COUNTA(C3:L17)-COUNTUNIQUE(C3:L17)<>0,""DUPLICATE PICKS DETECTED"",""Next Pick: ""&Misc!W25)"),"Next Pick: Team 1") -> Next Pick: Team 1
A2: Top Available | C2: Team 1 | D2: Team 2 | E2: Team 3 | F2: Team 4 | G2: Team 5 | H2: Team 6 | I2: Team 7 | J2: Team 8 | K2: Team 9 | L2: Team 10 | M2: Team 11 | N2: Team 12 | O2: Team 13 | P2: Team 14 | Q2: Team 15 | R2: Team 16 | S2: Team 17 | T2: Team 18 | U2: Team 19 | V2: Team 20
A3: =IFERROR(__xludf.DUMMYFUNCTION("IFERROR(QUERY('Data Format'!A2:B31,""SELECT B WHERE B IS NOT NULL LIMIT ""&ROWS($B$3:$B$24)),""Wait for it..."")"),"Wait for it...") -> Wait for it... | B3: 1 | W3: →
B4: 2 | W4: ←
B5: 3 | W5: →
B6: 4 | W6: ←
B7: 5 | W7: →
B8: 6 | W8: ←
B9: 7 | W9: →
B10: 8 | W10: ←
B11: 9 | W11: →
B12: 10 | W12: ←
B13: 11 | W13: →
B14: 12 | W14: ←
B15: 13 | W15: →
... B24: 22 | W24: ←
A25: Total | C25: =C2 -> Team 1 | D25: =D2 -> Team 2 | E25: =E2 -> Team 3 | F25: =F2 -> Team 4 | G25: =G2 -> Team 5 | H25: =H2 -> Team 6 | I25: =I2 -> Team 7 | J25: =J2 -> Team 8 | ... V25: =V2 -> Team 20
A26: ="RB: "&COUNTIF($C$3:$V$24,"*RB -*") -> RB: 0 | C26: {="RB: "&COUNTIF({C$3:C$24;Keepers!B$2:B$21},"*RB -*")} -> RB: 0 | D26: {="RB: "&COUNTIF({D$3:D$24;Keepers!C$2:C$21},"*RB -*")} -> RB: 0 | E26: {="RB: "&COUNTIF({E$3:E$24;Keepers!D$2:D$21},"*RB -*")} -> RB: 0 | F26: {="RB: "&COUNTIF({F$3:F$24;Keepers!E$2:E$21},"*RB -*")} -> RB: 0 | G26: {="RB: "&COUNTIF({G$3:G$24;Keepers!F$2:F$21},"*RB -*")} -> RB: 0 | H26: {="RB: "&COUNTIF({H$3:H$24;Keepers!G$2:G$21},"*RB -*")} -> RB: 0 | I26: {="RB: "&COUNTIF({I$3:I$24;Keepers!H$2:H$21},"*RB -*")} -> RB: 0 | J26: {="RB: "&COUNTIF({J$3:J$24;Keepers!I$2:I$21},"*RB -*")} -> RB: 0 | ... V26: {="RB: "&COUNTIF({V$3:V$24;Keepers!U$2:U$21},"*RB -*")} -> RB: 0
A27: ="WR: "&COUNTIF($C$3:$V$24,"*WR -*") -> WR: 0 | C27: {="WR: "&COUNTIF({C$3:C$24;Keepers!B$2:B$21},"*WR -*")} -> WR: 0 | D27: {="WR: "&COUNTIF({D$3:D$24;Keepers!C$2:C$21},"*WR -*")} -> WR: 0 | E27: {="WR: "&COUNTIF({E$3:E$24;Keepers!D$2:D$21},"*WR -*")} -> WR: 0 | F27: {="WR: "&COUNTIF({F$3:F$24;Keepers!E$2:E$21},"*WR -*")} -> WR: 0 | G27: {="WR: "&COUNTIF({G$3:G$24;Keepers!F$2:F$21},"*WR -*")} -> WR: 0 | H27: {="WR: "&COUNTIF({H$3:H$24;Keepers!G$2:G$21},"*WR -*")} -> WR: 0 | I27: {="WR: "&COUNTIF({I$3:I$24;Keepers!H$2:H$21},"*WR -*")} -> WR: 0 | J27: {="WR: "&COUNTIF({J$3:J$24;Keepers!I$2:I$21},"*WR -*")} -> WR: 0 | ... V27: {="WR: "&COUNTIF({V$3:V$24;Keepers!U$2:U$21},"*WR -*")} -> WR: 0
A28: ="QB: "&COUNTIF($C$3:$V$24,"*QB -*") -> QB: 0 | C28: {="QB: "&COUNTIF({C$3:C$24;Keepers!B$2:B$21},"*QB -*")} -> QB: 0 | D28: {="QB: "&COUNTIF({D$3:D$24;Keepers!C$2:C$21},"*QB -*")} -> QB: 0 | E28: {="QB: "&COUNTIF({E$3:E$24;Keepers!D$2:D$21},"*QB -*")} -> QB: 0 | F28: {="QB: "&COUNTIF({F$3:F$24;Keepers!E$2:E$21},"*QB -*")} -> QB: 0 | G28: {="QB: "&COUNTIF({G$3:G$24;Keepers!F$2:F$21},"*QB -*")} -> QB: 0 | H28: {="QB: "&COUNTIF({H$3:H$24;Keepers!G$2:G$21},"*QB -*")} -> QB: 0 | I28: {="QB: "&COUNTIF({I$3:I$24;Keepers!H$2:H$21},"*QB -*")} -> QB: 0 | J28: {="QB: "&COUNTIF({J$3:J$24;Keepers!I$2:I$21},"*QB -*")} -> QB: 0 | ... V28: {="QB: "&COUNTIF({V$3:V$24;Keepers!U$2:U$21},"*QB -*")} -> QB: 0
A29: ="TE: "&COUNTIF($C$3:$V$24,"*TE -*") -> TE: 0 | C29: {="TE: "&COUNTIF({C$3:C$24;Keepers!B$2:B$21},"*TE -*")} -> TE: 0 | D29: {="TE: "&COUNTIF({D$3:D$24;Keepers!C$2:C$21},"*TE -*")} -> TE: 0 | E29: {="TE: "&COUNTIF({E$3:E$24;Keepers!D$2:D$21},"*TE -*")} -> TE: 0 | F29: {="TE: "&COUNTIF({F$3:F$24;Keepers!E$2:E$21},"*TE -*")} -> TE: 0 | G29: {="TE: "&COUNTIF({G$3:G$24;Keepers!F$2:F$21},"*TE -*")} -> TE: 0 | H29: {="TE: "&COUNTIF({H$3:H$24;Keepers!G$2:G$21},"*TE -*")} -> TE: 0 | I29: {="TE: "&COUNTIF({I$3:I$24;Keepers!H$2:H$21},"*TE -*")} -> TE: 0 | J29: {="TE: "&COUNTIF({J$3:J$24;Keepers!I$2:I$21},"*TE -*")} -> TE: 0 | ... V29: {="TE: "&COUNTIF({V$3:V$24;Keepers!U$2:U$21},"*TE -*")} -> TE: 0
A30: ="DST: "&COUNTIF($C$3:$V$24,"*DST -*") -> DST: 0 | C30: {="DST: "&COUNTIF({C$3:C$24;Keepers!B$2:B$21},"*DST -*")} -> DST: 0 | D30: {="DST: "&COUNTIF({D$3:D$24;Keepers!C$2:C$21},"*DST -*")} -> DST: 0 | E30: {="DST: "&COUNTIF({E$3:E$24;Keepers!D$2:D$21},"*DST -*")} -> DST: 0 | F30: {="DST: "&COUNTIF({F$3:F$24;Keepers!E$2:E$21},"*DST -*")} -> DST: 0 | G30: {="DST: "&COUNTIF({G$3:G$24;Keepers!F$2:F$21},"*DST -*")} -> DST: 0 | H30: {="DST: "&COUNTIF({H$3:H$24;Keepers!G$2:G$21},"*DST -*")} -> DST: 0 | I30: {="DST: "&COUNTIF({I$3:I$24;Keepers!H$2:H$21},"*DST -*")} -> DST: 0 | J30: {="DST: "&COUNTIF({J$3:J$24;Keepers!I$2:I$21},"*DST -*")} -> DST: 0 | ... V30: {="DST: "&COUNTIF({V$3:V$24;Keepers!U$2:U$21},"*DST -*")} -> DST: 0
A31: ="K: "&COUNTIF($C$3:$V$24,"*K -*") -> K: 0 | C31: {="K: "&COUNTIF({C$3:C$24;Keepers!B$2:B$21},"*K -*")} -> K: 0 | D31: {="K: "&COUNTIF({D$3:D$24;Keepers!C$2:C$21},"*K -*")} -> K: 0 | E31: {="K: "&COUNTIF({E$3:E$24;Keepers!D$2:D$21},"*K -*")} -> K: 0 | F31: {="K: "&COUNTIF({F$3:F$24;Keepers!E$2:E$21},"*K -*")} -> K: 0 | G31: {="K: "&COUNTIF({G$3:G$24;Keepers!F$2:F$21},"*K -*")} -> K: 0 | H31: {="K: "&COUNTIF({H$3:H$24;Keepers!G$2:G$21},"*K -*")} -> K: 0 | I31: {="K: "&COUNTIF({I$3:I$24;Keepers!H$2:H$21},"*K -*")} -> K: 0 | J31: {="K: "&COUNTIF({J$3:J$24;Keepers!I$2:I$21},"*K -*")} -> K: 0 | ... V31: {="K: "&COUNTIF({V$3:V$24;Keepers!U$2:U$21},"*K -*")} -> K: 0

Sheet Keepers
B1: ='Draft Board'!C2 -> Team 1 | C1: ='Draft Board'!D2 -> Team 2 | D1: ='Draft Board'!E2 -> Team 3 | E1: ='Draft Board'!F2 -> Team 4 | F1: ='Draft Board'!G2 -> Team 5 | G1: ='Draft Board'!H2 -> Team 6 | H1: ='Draft Board'!I2 -> Team 7 | I1: ='Draft Board'!J2 -> Team 8 | ... U1: ='Draft Board'!V2 -> Team 20
A2: 1
A3: 2
A4: 3
A5: 4
A6: 5
A7: 6
A8: 7
A9: 8
A10: 9
A11: 10
A12: 11
A13: 12
... A21: 20
B22: =B1 -> Team 1 | C22: =C1 -> Team 2 | D22: =D1 -> Team 3 | E22: =E1 -> Team 4 | F22: =F1 -> Team 5 | G22: =G1 -> Team 6 | H22: =H1 -> Team 7 | I22: =I1 -> Team 8 | ... U22: =U1 -> Team 20

Sheet Drafted
A1: ALL | B1: RB | C1: WR | D1: QB | E1: TE | F1: DEF | G1: PK
A2: =IFERROR(__xludf.DUMMYFUNCTION("{ArrayFormula(unique(transpose(split(concatenate('Draft Board'!C3:V24&""%""),""%""))));SORT(UNIQUE({'Auction Draft Board'!C6:C25;'Auction Draft Board'!E6:E25;'Auction Draft Board'!G6:G25;'Auction Draft Board'!I6:I25;'Auction Draft Board'!K6:K25;'Auction D"&"raft Board'!M6:M25;'Auction Draft Board'!O6:O25;'Auction Draft Board'!Q6:Q25;'Auction Draft Board'!S6:S25;'Auction Draft Board'!U6:U25;'Auction Draft Board'!W6:W25;'Auction Draft Board'!Y6:Y25;'Auction Draft Board'!AA6:AA25;'Auction Draft Board'!AC6:AC25;"&"'Auction Draft Board'!AE6:AE25;'Auction Draft Board'!AG6:AG25;'Auction Draft Board'!AI6:AI25;'Auction Draft Board'!AK6:AK25;'Auction Draft Board'!AM6:AM25;'Auction Draft Board'!AO6:AO25}))}"),"%%%%%%%%%%%%%%%%%%%%%%%%%%%%%%%%%%%%%%%%%%%%%%%%%%%%%%%%%%%%%%%%%%%%%%%%%%%%%%%%%%%%%%%%%%%%%%%%%%%%%%%%%%%%%%%%%%%%%%%%%%%%%%%%%%%%%%%%%%%%%%%%%%%%%%%%%%%%%%%%%%%%%%%%%%%%%%%%%%%%%%%%%%%%%%%%%%%%%%%%%%%%%%%%%%%%%%%%%%%%%%%%%%%%%%%%%%%%%%%%%%%%%%%%%%%%%%%"&"%%%%%%%%%%%%%%%%%%%%%%%%%%%%%%%%%%%%%%%%%%%%%%%%%%%%%%%%%%%%%%%%%%%%%%%%%%%%%%%%%%%%%%%%%%%%%%%%%%%%%%%%%%%%%%%%%%%%%%%%%%%%%%%%%%%%%%%%%%%%%%%%%%%%%%%%%%%%%%%%%%%%%%%%%%%%%%%%%%%%%%%%%") -> %%%%%%%%%%%%%%%%%%%%%%%%%%%%%%%%%%%%%%%%%%%%%%%%%%%%%%%%%%%%%%%%%%%%%%%%%%%%%%%%%%%%%%%%%%%%%%%%%%%%%%%%%%%%%%%%%%%%%%%%%%%%%%%%%%%%%%%%%%%%%%%%%%%%%%%%%%%%%%%%%%%%%%%%%%%%%%%%%%%%%%%%%%%%%%%%%%%%%%%%%%%%%%%%%%%%%%%%%%%%%%%%%%%%%%%%%%%%%%%%%%%%%%%%%%%%%%%%%%%%%%%%%%%%%%%%%%%%%%%%%%%%%%%%%%%%%%%%%%%%%%%%%%%%%%%%%%%%%%%%%%%%%%%%%%%%%%%%%%%%%%%%%%%%%%%%%%%%%%%%%%%%%%%%%%%%%%%%%%%%%%%%%%%%%%%%%%%%%%%%%%%%%%%%%%%%%%%%%%%%%%%%%%%%%%%%%%%%%%%% | B2: =IFERROR(__xludf.DUMMYFUNCTION("IFERROR(QUERY($A:$A,""SELECT A WHERE A CONTAINS 'RB -'""),"""")"),"") | C2: =IFERROR(__xludf.DUMMYFUNCTION("IFERROR(QUERY($A:$A,""SELECT A WHERE A CONTAINS 'WR -'""),"""")"),"") | D2: =IFERROR(__xludf.DUMMYFUNCTION("IFERROR(QUERY($A:$A,""SELECT A WHERE A CONTAINS 'QB -'""),"""")"),"") | E2: =IFERROR(__xludf.DUMMYFUNCTION("IFERROR(QUERY($A:$A,""SELECT A WHERE A CONTAINS 'TE -'""),"""")"),"") | F2: =IFERROR(__xludf.DUMMYFUNCTION("IFERROR(QUERY($A:$A,""SELECT A WHERE A CONTAINS 'DST -'""),"""")"),"") | G2: =IFERROR(__xludf.DUMMYFUNCTION("IFERROR(QUERY($A:$A,""SELECT A WHERE A CONTAINS 'PK -'""),"""")"),"")
A3: =IFERROR(__xludf.DUMMYFUNCTION("""COMPUTED_VALUE"""),"#REF!") -> #REF!

Sheet Best Available
A1: ALL | B1: RB | C1: WR | D1: QB | E1: TE | F1: DEF | G1: PK
A2: =IFERROR(__xludf.DUMMYFUNCTION("QUERY('Data Format'!A2:B21,""SELECT B WHERE B IS NOT NULL LIMIT ""&ROWs(A2:A21))"),"#N/A") -> #N/A | B2: =IFERROR(__xludf.DUMMYFUNCTION("QUERY('Data Format'!A2:B21,""SELECT B WHERE B CONTAINS 'RB -' LIMIT ""&ROWs(A2:A21))"),"#N/A") -> #N/A | C2: =IFERROR(__xludf.DUMMYFUNCTION("QUERY('Data Format'!A2:B21,""SELECT B WHERE B CONTAINS 'WR -' LIMIT ""&ROWs(A2:A21))"),"#N/A") -> #N/A | D2: =IFERROR(__xludf.DUMMYFUNCTION("QUERY('Data Format'!A2:B21,""SELECT B WHERE B CONTAINS 'QB -' LIMIT ""&ROWs(A2:A21))"),"#N/A") -> #N/A | E2: =IFERROR(__xludf.DUMMYFUNCTION("QUERY('Data Format'!A2:B21,""SELECT B WHERE B CONTAINS 'TE -' LIMIT ""&ROWs(A2:A21))"),"#N/A") -> #N/A | F2: =IFERROR(__xludf.DUMMYFUNCTION("QUERY('Data Format'!A2:B21,""SELECT B WHERE B CONTAINS 'DST -' LIMIT ""&ROWs(A2:A21))"),"#N/A") -> #N/A | G2: =IFERROR(__xludf.DUMMYFUNCTION("QUERY('Data Format'!A2:B21,""SELECT B WHERE B CONTAINS 'K -' LIMIT ""&ROWs(A2:A21))"),"#N/A") -> #N/A

Sheet Manual Data Import
A1: Rank | B1: Player (Bye) | C1: POS | D1: ESPN | E1: Sleeper | F1: CBS | G1: RTSports | H1: Fantrax | I1: AVG | J1: Real-Time | O1: https://www.fantasypros.com/nfl/adp/overall.php
A2: 1 | B2: Jahmyr Gibbs DET (6) | C2: RB1 | D2: 1 | E2: 1 | F2: 1 | G2: 1 | H2: 1 | I2: 1 | J2: 1
A3: 2 | B3: Bijan Robinson ATL (11) | C3: RB2 | D3: 2 | E3: 2 | F3: 2 | G3: 2 | H3: 2 | I3: 2 | J3: 2
A4: 3 | B4: Ja'Marr Chase CIN (6) | C4: WR1 | D4: 3 | E4: 3 | F4: 3 | G4: 3 | H4: 3 | I4: 3 | J4: 3
A5: 4 | B5: Puka Nacua LAR (11) | C5: WR2 | D5: 4 | E5: 4 | F5: 5 | G5: 4 | H5: 4 | I5: 4.2 | J5: 4
A6: 5 | B6: Christian McCaffrey SF (8) | C6: RB3 | D6: 6 | E6: 5 | F6: 7 | G6: 5 | H6: 5 | I6: 5.6 | J6: 5
A7: 6 | B7: Jaxon Smith-Njigba SEA (11) | C7: WR3 | D7: 5 | E7: 6 | F7: 6 | G7: 6 | H7: 6 | I7: 5.8 | J7: 6
A8: 7 | B8: Jonathan Taylor IND (13) | C8: RB4 | D8: 7 | E8: 7 | F8: 4 | G8: 7 | H8: 7 | I8: 6.4 | J8: 7
A9: 8 | B9: Amon-Ra St. Brown DET (6) | C9: WR4 | D9: 8 | E9: 8 | F9: 8 | G9: 8 | H9: 8 | I9: 8 | J9: 8
A10: 9 | B10: James Cook III BUF (7) | C10: RB5 | D10: 12 | E10: 10 | F10: 9 | G10: 9 | H10: 9 | I10: 9.8 | J10: 10 -1
A11: 10 | B11: De'Von Achane MIA (6) | C11: RB6 | D11: 10 | E11: 12 | F11: 10 | G11: 10 | H11: 13 | I11: 11 | J11: 13 -3
A12: 11 | B12: CeeDee Lamb DAL (14) | C12: WR5 | D12: 9 | E12: 9 | F12: 14 | G12: 13 | H12: 11 | I12: 11.2 | J12: 9 +2
A13: 12 | B13: Justin Jefferson MIN (6) | C13: WR6 | D13: 11 | E13: 11 | F13: 16 | G13: 12 | H13: 10 | I13: 12 | J13: 12
A14: 13 | B14: Saquon Barkley PHI (10) | C14: RB7 | D14: 13 | E14: 13 | F14: 13 | G14: 14 | H14: 14 | I14: 13.4 | J14: 11 +2
A15: 14 | B15: Chase Brown CIN (6) | C15: RB8 | D15: 20 | E15: 16 | F15: 11 | G15: 11 | H15: 12 | I15: 14 | J15: 14
A16: 15 | B16: Ashton Jeanty LV (13) | C16: RB9 | D16: 14 | E16: 14 | F16: 15 | G16: 16 | H16: 18 | I16: 15.4 | J16: 20 -5
A17: 16 | B17: Derrick Henry BAL (13) | C17: RB10 | D17: 16 | E17: 20 | F17: 12 | G17: 18 | H17: 20 | I17: 17.2 | J17: 18 -2
A18: 17 | B18: Omarion Hampton LAC (7) | C18: RB11 | D18: 24 | E18: 15 | F18: 20 | G18: 15 | H18: 15 | I18: 17.8 | J18: 15 +2
A19: 18 | B19: Kenneth Walker III KC (5) | C19: RB12 | D19: 21 | E19: 19 | F19: 17 | G19: 17 | H19: 16 | I19: 18 | J19: 16 +2
A20: 19 | B20: Drake London ATL (11) | C20: WR7 | D20: 15 | E20: 17 | F20: 18 | G20: 21 | H20: 21 | I20: 18.4 | J20: 19
A21: 20 | B21: A.J. Brown NE (11) | C21: WR8 | D21: 25 | E21: 18 | F21: 21 | G21: 19 | H21: 17 | I21: 20 | J21: 17 +3
A22: 21 | B22: Trey McBride ARI (14) | C22: TE1 | D22: 17 | E22: 21 | F22: 28 | G22: 20 | H22: 25 | I22: 22.2 | J22: 25 -4
A23: 22 | B23: Brock Bowers LV (13) | C23: TE2 | D23: 23 | E23: 23 | F23: 27 | G23: 24 | H23: 19 | I23: 23.2 | J23: 22
A24: 23 | B24: Josh Allen BUF (7) | C24: QB1 | D24: 18 | E24: 22 | F24: 19 | G24: 27 | H24: 31 | I24: 23.4 | J24: 24 -1
A25: 24 | B25: Nico Collins HOU (8) | C25: WR9 | D25: 26 | E25: 25 | F25: 25 | G25: 25 | H25: 22 | I25: 24.6 | J25: 21 +3
A26: 25 | B26: George Pickens DAL (14) | C26: WR10 | D26: 27 | E26: 24 | F26: 22 | G26: 26 | H26: 26 | I26: 25 | J26: 23 +2
A27: 26 | B27: Rashee Rice KC (5) | C27: WR11 | D27: 19 | E27: 27 | F27: 23 | G27: 33 | H27: 28 | I27: 26 | J27: 30 -4
A28: 27 | B28: Chris Olave NO (8) | C28: WR12 | D28: 28 | E28: 30 | F28: 29 | G28: 22 | H28: 24 | I28: 26.6 | J28: 28 -1
A29: 28 | B29: Jeremiyah Love ARI (14) | C29: RB13 | D29: 22 | E29: 26 | F29: 30 | G29: 29 | H29: 33 | I29: 28 | J29: 31 -3
A30: 29 | B30: Malik Nabers NYG (8) | C30: WR13 | D30: 30 | E30: 28 | F30: 31 | G30: 28 | H30: 23 | I30: 28 | J30: 26 +3
A31: 30 | B31: Kyren Williams LAR (11) | C31: RB14 | D31: 38 | E31: 29 | F31: 24 | G31: 30 | H31: 27 | I31: 29.6 | J31: 27 +3
A32: 31 | B32: Javonte Williams DAL (14) | C32: RB15 | D32: 31 | E32: 35 | F32: 33 | G32: 23 | H32: 30 | I32: 30.4 | J32: 32 -1
A33: 32 | B33: Josh Jacobs GB (11) | C33: RB16 | D33: 33 | E33: 31 | F33: 26 | G33: 31 | H33: 40 | I33: 32.2 | J33: 33 -1
A34: 33 | B34: Breece Hall NYJ (13) | C34: RB17 | D34: 29 | E34: 33 | F34: 37 | G34: 32 | H34: 32 | I34: 32.6 | J34: 35 -2
A35: 34 | B35: DeVonta Smith PHI (10) | C35: WR14 | D35: 36 | E35: 36 | F35: 36 | G35: 36 | H35: 29 | I35: 34.6 | J35: 29 +5
... A43: 42 | B43: Tee Higgins CIN (6) | C43: WR19 | D43: 51 | E43: 34 | F43: 39 | G43: 51 | H43: 37 | I43: 42.4 | J43: 34 +8
A44: 43 | B44: Colston Loveland CHI (10) | C44: TE3 | D44: 41 | E44: 39 | F44: 45 | G44: 48 | H44: 42 | I44: 43 | J44: 43
A45: 44 | B45: Ladd McConkey LAC (7) | C45: WR20 | D45: 45 | E45: 38 | F45: 43 | G45: 44 | H45: 54 | I45: 44.8 | J45: 38 +6
A46: 45 | B46: Bucky Irving TB (10) | C46: RB20 | D46: 49 | E46: 41 | F46: 40 | G46: 39 | H46: 57 | I46: 45.2 | J46: 47 -2
A47: 46 | B47: D'Andre Swift CHI (10) | C47: RB21 | D47: 56 | E47: 56 | F47: 35 | G47: 43 | H47: 44 | I47: 46.8 | J47: 46
...

Sheet Data Format
A1: Formatted | B1: Available
A2: =IFERROR(__xludf.DUMMYFUNCTION("IFERROR(REGEXEXTRACT('Manual Data Import'!B2, ""^(.*)\s+[A-Z]{2,4}\s+\(\d+\)$""),'Manual Data Import'!B2) & CHAR(10) & IFERROR(REGEXREPLACE('Manual Data Import'!C2, ""\d+$"", """")) &"" - ""& IFERROR(REGEXEXTRACT('Manual Data Import'!B2, ""([A-Z]{2,4})\"&"s+\(\d+\)$"")) & "" (""& IFERROR(REGEXEXTRACT('Manual Data Import'!B2, ""\((\d+)\)"")) & "")"""),"Jahmyr Gibbs RB - DET (6)") -> Jahmyr Gibbs RB - DET (6) | B2: =IFERROR(IF(COUNTIF('Draft Board'!$C$3:$V$24,A2)+COUNTIF(Keepers!$B$2:$U$21,A2)+COUNTIF('Auction Draft Board'!$C$6:$AP$25,A2)>0,"",A2),"")
A3: =IFERROR(__xludf.DUMMYFUNCTION("IFERROR(REGEXEXTRACT('Manual Data Import'!B3, ""^(.*)\s+[A-Z]{2,4}\s+\(\d+\)$""),'Manual Data Import'!B3) & CHAR(10) & IFERROR(REGEXREPLACE('Manual Data Import'!C3, ""\d+$"", """")) &"" - ""& IFERROR(REGEXEXTRACT('Manual Data Import'!B3, ""([A-Z]{2,4})\"&"s+\(\d+\)$"")) & "" (""& IFERROR(REGEXEXTRACT('Manual Data Import'!B3, ""\((\d+)\)"")) & "")"""),"Bijan Robinson RB - ATL (11)") -> Bijan Robinson RB - ATL (11) | B3: =IFERROR(IF(COUNTIF('Draft Board'!$C$3:$V$24,A3)+COUNTIF(Keepers!$B$2:$U$21,A3)+COUNTIF('Auction Draft Board'!$C$6:$AP$25,A3)>0,"",A3),"")
A4: =IFERROR(__xludf.DUMMYFUNCTION("IFERROR(REGEXEXTRACT('Manual Data Import'!B4, ""^(.*)\s+[A-Z]{2,4}\s+\(\d+\)$""),'Manual Data Import'!B4) & CHAR(10) & IFERROR(REGEXREPLACE('Manual Data Import'!C4, ""\d+$"", """")) &"" - ""& IFERROR(REGEXEXTRACT('Manual Data Import'!B4, ""([A-Z]{2,4})\"&"s+\(\d+\)$"")) & "" (""& IFERROR(REGEXEXTRACT('Manual Data Import'!B4, ""\((\d+)\)"")) & "")"""),"Ja'Marr Chase WR - CIN (6)") -> Ja'Marr Chase WR - CIN (6) | B4: =IFERROR(IF(COUNTIF('Draft Board'!$C$3:$V$24,A4)+COUNTIF(Keepers!$B$2:$U$21,A4)+COUNTIF('Auction Draft Board'!$C$6:$AP$25,A4)>0,"",A4),"")
A5: =IFERROR(__xludf.DUMMYFUNCTION("IFERROR(REGEXEXTRACT('Manual Data Import'!B5, ""^(.*)\s+[A-Z]{2,4}\s+\(\d+\)$""),'Manual Data Import'!B5) & CHAR(10) & IFERROR(REGEXREPLACE('Manual Data Import'!C5, ""\d+$"", """")) &"" - ""& IFERROR(REGEXEXTRACT('Manual Data Import'!B5, ""([A-Z]{2,4})\"&"s+\(\d+\)$"")) & "" (""& IFERROR(REGEXEXTRACT('Manual Data Import'!B5, ""\((\d+)\)"")) & "")"""),"Puka Nacua WR - LAR (11)") -> Puka Nacua WR - LAR (11) | B5: =IFERROR(IF(COUNTIF('Draft Board'!$C$3:$V$24,A5)+COUNTIF(Keepers!$B$2:$U$21,A5)+COUNTIF('Auction Draft Board'!$C$6:$AP$25,A5)>0,"",A5),"")
A6: =IFERROR(__xludf.DUMMYFUNCTION("IFERROR(REGEXEXTRACT('Manual Data Import'!B6, ""^(.*)\s+[A-Z]{2,4}\s+\(\d+\)$""),'Manual Data Import'!B6) & CHAR(10) & IFERROR(REGEXREPLACE('Manual Data Import'!C6, ""\d+$"", """")) &"" - ""& IFERROR(REGEXEXTRACT('Manual Data Import'!B6, ""([A-Z]{2,4})\"&"s+\(\d+\)$"")) & "" (""& IFERROR(REGEXEXTRACT('Manual Data Import'!B6, ""\((\d+)\)"")) & "")"""),"Christian McCaffrey RB - SF (8)") -> Christian McCaffrey RB - SF (8) | B6: =IFERROR(IF(COUNTIF('Draft Board'!$C$3:$V$24,A6)+COUNTIF(Keepers!$B$2:$U$21,A6)+COUNTIF('Auction Draft Board'!$C$6:$AP$25,A6)>0,"",A6),"")
A7: =IFERROR(__xludf.DUMMYFUNCTION("IFERROR(REGEXEXTRACT('Manual Data Import'!B7, ""^(.*)\s+[A-Z]{2,4}\s+\(\d+\)$""),'Manual Data Import'!B7) & CHAR(10) & IFERROR(REGEXREPLACE('Manual Data Import'!C7, ""\d+$"", """")) &"" - ""& IFERROR(REGEXEXTRACT('Manual Data Import'!B7, ""([A-Z]{2,4})\"&"s+\(\d+\)$"")) & "" (""& IFERROR(REGEXEXTRACT('Manual Data Import'!B7, ""\((\d+)\)"")) & "")"""),"Jaxon Smith-Njigba WR - SEA (11)") -> Jaxon Smith-Njigba WR - SEA (11) | B7: =IFERROR(IF(COUNTIF('Draft Board'!$C$3:$V$24,A7)+COUNTIF(Keepers!$B$2:$U$21,A7)+COUNTIF('Auction Draft Board'!$C$6:$AP$25,A7)>0,"",A7),"")
A8: =IFERROR(__xludf.DUMMYFUNCTION("IFERROR(REGEXEXTRACT('Manual Data Import'!B8, ""^(.*)\s+[A-Z]{2,4}\s+\(\d+\)$""),'Manual Data Import'!B8) & CHAR(10) & IFERROR(REGEXREPLACE('Manual Data Import'!C8, ""\d+$"", """")) &"" - ""& IFERROR(REGEXEXTRACT('Manual Data Import'!B8, ""([A-Z]{2,4})\"&"s+\(\d+\)$"")) & "" (""& IFERROR(REGEXEXTRACT('Manual Data Import'!B8, ""\((\d+)\)"")) & "")"""),"Jonathan Taylor RB - IND (13)") -> Jonathan Taylor RB - IND (13) | B8: =IFERROR(IF(COUNTIF('Draft Board'!$C$3:$V$24,A8)+COUNTIF(Keepers!$B$2:$U$21,A8)+COUNTIF('Auction Draft Board'!$C$6:$AP$25,A8)>0,"",A8),"")
A9: =IFERROR(__xludf.DUMMYFUNCTION("IFERROR(REGEXEXTRACT('Manual Data Import'!B9, ""^(.*)\s+[A-Z]{2,4}\s+\(\d+\)$""),'Manual Data Import'!B9) & CHAR(10) & IFERROR(REGEXREPLACE('Manual Data Import'!C9, ""\d+$"", """")) &"" - ""& IFERROR(REGEXEXTRACT('Manual Data Import'!B9, ""([A-Z]{2,4})\"&"s+\(\d+\)$"")) & "" (""& IFERROR(REGEXEXTRACT('Manual Data Import'!B9, ""\((\d+)\)"")) & "")"""),"Amon-Ra St. Brown WR - DET (6)") -> Amon-Ra St. Brown WR - DET (6) | B9: =IFERROR(IF(COUNTIF('Draft Board'!$C$3:$V$24,A9)+COUNTIF(Keepers!$B$2:$U$21,A9)+COUNTIF('Auction Draft Board'!$C$6:$AP$25,A9)>0,"",A9),"")
A10: =IFERROR(__xludf.DUMMYFUNCTION("IFERROR(REGEXEXTRACT('Manual Data Import'!B10, ""^(.*)\s+[A-Z]{2,4}\s+\(\d+\)$""),'Manual Data Import'!B10) & CHAR(10) & IFERROR(REGEXREPLACE('Manual Data Import'!C10, ""\d+$"", """")) &"" - ""& IFERROR(REGEXEXTRACT('Manual Data Import'!B10, ""([A-Z]{2,"&"4})\s+\(\d+\)$"")) & "" (""& IFERROR(REGEXEXTRACT('Manual Data Import'!B10, ""\((\d+)\)"")) & "")"""),"James Cook III RB - BUF (7)") -> James Cook III RB - BUF (7) | B10: =IFERROR(IF(COUNTIF('Draft Board'!$C$3:$V$24,A10)+COUNTIF(Keepers!$B$2:$U$21,A10)+COUNTIF('Auction Draft Board'!$C$6:$AP$25,A10)>0,"",A10),"")
A11: =IFERROR(__xludf.DUMMYFUNCTION("IFERROR(REGEXEXTRACT('Manual Data Import'!B11, ""^(.*)\s+[A-Z]{2,4}\s+\(\d+\)$""),'Manual Data Import'!B11) & CHAR(10) & IFERROR(REGEXREPLACE('Manual Data Import'!C11, ""\d+$"", """")) &"" - ""& IFERROR(REGEXEXTRACT('Manual Data Import'!B11, ""([A-Z]{2,"&"4})\s+\(\d+\)$"")) & "" (""& IFERROR(REGEXEXTRACT('Manual Data Import'!B11, ""\((\d+)\)"")) & "")"""),"De'Von Achane RB - MIA (6)") -> De'Von Achane RB - MIA (6) | B11: =IFERROR(IF(COUNTIF('Draft Board'!$C$3:$V$24,A11)+COUNTIF(Keepers!$B$2:$U$21,A11)+COUNTIF('Auction Draft Board'!$C$6:$AP$25,A11)>0,"",A11),"")
A12: =IFERROR(__xludf.DUMMYFUNCTION("IFERROR(REGEXEXTRACT('Manual Data Import'!B12, ""^(.*)\s+[A-Z]{2,4}\s+\(\d+\)$""),'Manual Data Import'!B12) & CHAR(10) & IFERROR(REGEXREPLACE('Manual Data Import'!C12, ""\d+$"", """")) &"" - ""& IFERROR(REGEXEXTRACT('Manual Data Import'!B12, ""([A-Z]{2,"&"4})\s+\(\d+\)$"")) & "" (""& IFERROR(REGEXEXTRACT('Manual Data Import'!B12, ""\((\d+)\)"")) & "")"""),"CeeDee Lamb WR - DAL (14)") -> CeeDee Lamb WR - DAL (14) | B12: =IFERROR(IF(COUNTIF('Draft Board'!$C$3:$V$24,A12)+COUNTIF(Keepers!$B$2:$U$21,A12)+COUNTIF('Auction Draft Board'!$C$6:$AP$25,A12)>0,"",A12),"")
A13: =IFERROR(__xludf.DUMMYFUNCTION("IFERROR(REGEXEXTRACT('Manual Data Import'!B13, ""^(.*)\s+[A-Z]{2,4}\s+\(\d+\)$""),'Manual Data Import'!B13) & CHAR(10) & IFERROR(REGEXREPLACE('Manual Data Import'!C13, ""\d+$"", """")) &"" - ""& IFERROR(REGEXEXTRACT('Manual Data Import'!B13, ""([A-Z]{2,"&"4})\s+\(\d+\)$"")) & "" (""& IFERROR(REGEXEXTRACT('Manual Data Import'!B13, ""\((\d+)\)"")) & "")"""),"Justin Jefferson WR - MIN (6)") -> Justin Jefferson WR - MIN (6) | B13: =IFERROR(IF(COUNTIF('Draft Board'!$C$3:$V$24,A13)+COUNTIF(Keepers!$B$2:$U$21,A13)+COUNTIF('Auction Draft Board'!$C$6:$AP$25,A13)>0,"",A13),"")
A14: =IFERROR(__xludf.DUMMYFUNCTION("IFERROR(REGEXEXTRACT('Manual Data Import'!B14, ""^(.*)\s+[A-Z]{2,4}\s+\(\d+\)$""),'Manual Data Import'!B14) & CHAR(10) & IFERROR(REGEXREPLACE('Manual Data Import'!C14, ""\d+$"", """")) &"" - ""& IFERROR(REGEXEXTRACT('Manual Data Import'!B14, ""([A-Z]{2,"&"4})\s+\(\d+\)$"")) & "" (""& IFERROR(REGEXEXTRACT('Manual Data Import'!B14, ""\((\d+)\)"")) & "")"""),"Saquon Barkley RB - PHI (10)") -> Saquon Barkley RB - PHI (10) | B14: =IFERROR(IF(COUNTIF('Draft Board'!$C$3:$V$24,A14)+COUNTIF(Keepers!$B$2:$U$21,A14)+COUNTIF('Auction Draft Board'!$C$6:$AP$25,A14)>0,"",A14),"")
A15: =IFERROR(__xludf.DUMMYFUNCTION("IFERROR(REGEXEXTRACT('Manual Data Import'!B15, ""^(.*)\s+[A-Z]{2,4}\s+\(\d+\)$""),'Manual Data Import'!B15) & CHAR(10) & IFERROR(REGEXREPLACE('Manual Data Import'!C15, ""\d+$"", """")) &"" - ""& IFERROR(REGEXEXTRACT('Manual Data Import'!B15, ""([A-Z]{2,"&"4})\s+\(\d+\)$"")) & "" (""& IFERROR(REGEXEXTRACT('Manual Data Import'!B15, ""\((\d+)\)"")) & "")"""),"Chase Brown RB - CIN (6)") -> Chase Brown RB - CIN (6) | B15: =IFERROR(IF(COUNTIF('Draft Board'!$C$3:$V$24,A15)+COUNTIF(Keepers!$B$2:$U$21,A15)+COUNTIF('Auction Draft Board'!$C$6:$AP$25,A15)>0,"",A15),"")
A16: =IFERROR(__xludf.DUMMYFUNCTION("IFERROR(REGEXEXTRACT('Manual Data Import'!B16, ""^(.*)\s+[A-Z]{2,4}\s+\(\d+\)$""),'Manual Data Import'!B16) & CHAR(10) & IFERROR(REGEXREPLACE('Manual Data Import'!C16, ""\d+$"", """")) &"" - ""& IFERROR(REGEXEXTRACT('Manual Data Import'!B16, ""([A-Z]{2,"&"4})\s+\(\d+\)$"")) & "" (""& IFERROR(REGEXEXTRACT('Manual Data Import'!B16, ""\((\d+)\)"")) & "")"""),"Ashton Jeanty RB - LV (13)") -> Ashton Jeanty RB - LV (13) | B16: =IFERROR(IF(COUNTIF('Draft Board'!$C$3:$V$24,A16)+COUNTIF(Keepers!$B$2:$U$21,A16)+COUNTIF('Auction Draft Board'!$C$6:$AP$25,A16)>0,"",A16),"")
A17: =IFERROR(__xludf.DUMMYFUNCTION("IFERROR(REGEXEXTRACT('Manual Data Import'!B17, ""^(.*)\s+[A-Z]{2,4}\s+\(\d+\)$""),'Manual Data Import'!B17) & CHAR(10) & IFERROR(REGEXREPLACE('Manual Data Import'!C17, ""\d+$"", """")) &"" - ""& IFERROR(REGEXEXTRACT('Manual Data Import'!B17, ""([A-Z]{2,"&"4})\s+\(\d+\)$"")) & "" (""& IFERROR(REGEXEXTRACT('Manual Data Import'!B17, ""\((\d+)\)"")) & "")"""),"Derrick Henry RB - BAL (13)") -> Derrick Henry RB - BAL (13) | B17: =IFERROR(IF(COUNTIF('Draft Board'!$C$3:$V$24,A17)+COUNTIF(Keepers!$B$2:$U$21,A17)+COUNTIF('Auction Draft Board'!$C$6:$AP$25,A17)>0,"",A17),"")
A18: =IFERROR(__xludf.DUMMYFUNCTION("IFERROR(REGEXEXTRACT('Manual Data Import'!B18, ""^(.*)\s+[A-Z]{2,4}\s+\(\d+\)$""),'Manual Data Import'!B18) & CHAR(10) & IFERROR(REGEXREPLACE('Manual Data Import'!C18, ""\d+$"", """")) &"" - ""& IFERROR(REGEXEXTRACT('Manual Data Import'!B18, ""([A-Z]{2,"&"4})\s+\(\d+\)$"")) & "" (""& IFERROR(REGEXEXTRACT('Manual Data Import'!B18, ""\((\d+)\)"")) & "")"""),"Omarion Hampton RB - LAC (7)") -> Omarion Hampton RB - LAC (7) | B18: =IFERROR(IF(COUNTIF('Draft Board'!$C$3:$V$24,A18)+COUNTIF(Keepers!$B$2:$U$21,A18)+COUNTIF('Auction Draft Board'!$C$6:$AP$25,A18)>0,"",A18),"")
A19: =IFERROR(__xludf.DUMMYFUNCTION("IFERROR(REGEXEXTRACT('Manual Data Import'!B19, ""^(.*)\s+[A-Z]{2,4}\s+\(\d+\)$""),'Manual Data Import'!B19) & CHAR(10) & IFERROR(REGEXREPLACE('Manual Data Import'!C19, ""\d+$"", """")) &"" - ""& IFERROR(REGEXEXTRACT('Manual Data Import'!B19, ""([A-Z]{2,"&"4})\s+\(\d+\)$"")) & "" (""& IFERROR(REGEXEXTRACT('Manual Data Import'!B19, ""\((\d+)\)"")) & "")"""),"Kenneth Walker III RB - KC (5)") -> Kenneth Walker III RB - KC (5) | B19: =IFERROR(IF(COUNTIF('Draft Board'!$C$3:$V$24,A19)+COUNTIF(Keepers!$B$2:$U$21,A19)+COUNTIF('Auction Draft Board'!$C$6:$AP$25,A19)>0,"",A19),"")
A20: =IFERROR(__xludf.DUMMYFUNCTION("IFERROR(REGEXEXTRACT('Manual Data Import'!B20, ""^(.*)\s+[A-Z]{2,4}\s+\(\d+\)$""),'Manual Data Import'!B20) & CHAR(10) & IFERROR(REGEXREPLACE('Manual Data Import'!C20, ""\d+$"", """")) &"" - ""& IFERROR(REGEXEXTRACT('Manual Data Import'!B20, ""([A-Z]{2,"&"4})\s+\(\d+\)$"")) & "" (""& IFERROR(REGEXEXTRACT('Manual Data Import'!B20, ""\((\d+)\)"")) & "")"""),"Drake London WR - ATL (11)") -> Drake London WR - ATL (11) | B20: =IFERROR(IF(COUNTIF('Draft Board'!$C$3:$V$24,A20)+COUNTIF(Keepers!$B$2:$U$21,A20)+COUNTIF('Auction Draft Board'!$C$6:$AP$25,A20)>0,"",A20),"")
A21: =IFERROR(__xludf.DUMMYFUNCTION("IFERROR(REGEXEXTRACT('Manual Data Import'!B21, ""^(.*)\s+[A-Z]{2,4}\s+\(\d+\)$""),'Manual Data Import'!B21) & CHAR(10) & IFERROR(REGEXREPLACE('Manual Data Import'!C21, ""\d+$"", """")) &"" - ""& IFERROR(REGEXEXTRACT('Manual Data Import'!B21, ""([A-Z]{2,"&"4})\s+\(\d+\)$"")) & "" (""& IFERROR(REGEXEXTRACT('Manual Data Import'!B21, ""\((\d+)\)"")) & "")"""),"A.J. Brown WR - NE (11)") -> A.J. Brown WR - NE (11) | B21: =IFERROR(IF(COUNTIF('Draft Board'!$C$3:$V$24,A21)+COUNTIF(Keepers!$B$2:$U$21,A21)+COUNTIF('Auction Draft Board'!$C$6:$AP$25,A21)>0,"",A21),"")
A22: =IFERROR(__xludf.DUMMYFUNCTION("IFERROR(REGEXEXTRACT('Manual Data Import'!B22, ""^(.*)\s+[A-Z]{2,4}\s+\(\d+\)$""),'Manual Data Import'!B22) & CHAR(10) & IFERROR(REGEXREPLACE('Manual Data Import'!C22, ""\d+$"", """")) &"" - ""& IFERROR(REGEXEXTRACT('Manual Data Import'!B22, ""([A-Z]{2,"&"4})\s+\(\d+\)$"")) & "" (""& IFERROR(REGEXEXTRACT('Manual Data Import'!B22, ""\((\d+)\)"")) & "")"""),"Trey McBride TE - ARI (14)") -> Trey McBride TE - ARI (14) | B22: =IFERROR(IF(COUNTIF('Draft Board'!$C$3:$V$24,A22)+COUNTIF(Keepers!$B$2:$U$21,A22)+COUNTIF('Auction Draft Board'!$C$6:$AP$25,A22)>0,"",A22),"")
A23: =IFERROR(__xludf.DUMMYFUNCTION("IFERROR(REGEXEXTRACT('Manual Data Import'!B23, ""^(.*)\s+[A-Z]{2,4}\s+\(\d+\)$""),'Manual Data Import'!B23) & CHAR(10) & IFERROR(REGEXREPLACE('Manual Data Import'!C23, ""\d+$"", """")) &"" - ""& IFERROR(REGEXEXTRACT('Manual Data Import'!B23, ""([A-Z]{2,"&"4})\s+\(\d+\)$"")) & "" (""& IFERROR(REGEXEXTRACT('Manual Data Import'!B23, ""\((\d+)\)"")) & "")"""),"Brock Bowers TE - LV (13)") -> Brock Bowers TE - LV (13) | B23: =IFERROR(IF(COUNTIF('Draft Board'!$C$3:$V$24,A23)+COUNTIF(Keepers!$B$2:$U$21,A23)+COUNTIF('Auction Draft Board'!$C$6:$AP$25,A23)>0,"",A23),"")
A24: =IFERROR(__xludf.DUMMYFUNCTION("IFERROR(REGEXEXTRACT('Manual Data Import'!B24, ""^(.*)\s+[A-Z]{2,4}\s+\(\d+\)$""),'Manual Data Import'!B24) & CHAR(10) & IFERROR(REGEXREPLACE('Manual Data Import'!C24, ""\d+$"", """")) &"" - ""& IFERROR(REGEXEXTRACT('Manual Data Import'!B24, ""([A-Z]{2,"&"4})\s+\(\d+\)$"")) & "" (""& IFERROR(REGEXEXTRACT('Manual Data Import'!B24, ""\((\d+)\)"")) & "")"""),"Josh Allen QB - BUF (7)") -> Josh Allen QB - BUF (7) | B24: =IFERROR(IF(COUNTIF('Draft Board'!$C$3:$V$24,A24)+COUNTIF(Keepers!$B$2:$U$21,A24)+COUNTIF('Auction Draft Board'!$C$6:$AP$25,A24)>0,"",A24),"")
A25: =IFERROR(__xludf.DUMMYFUNCTION("IFERROR(REGEXEXTRACT('Manual Data Import'!B25, ""^(.*)\s+[A-Z]{2,4}\s+\(\d+\)$""),'Manual Data Import'!B25) & CHAR(10) & IFERROR(REGEXREPLACE('Manual Data Import'!C25, ""\d+$"", """")) &"" - ""& IFERROR(REGEXEXTRACT('Manual Data Import'!B25, ""([A-Z]{2,"&"4})\s+\(\d+\)$"")) & "" (""& IFERROR(REGEXEXTRACT('Manual Data Import'!B25, ""\((\d+)\)"")) & "")"""),"Nico Collins WR - HOU (8)") -> Nico Collins WR - HOU (8) | B25: =IFERROR(IF(COUNTIF('Draft Board'!$C$3:$V$24,A25)+COUNTIF(Keepers!$B$2:$U$21,A25)+COUNTIF('Auction Draft Board'!$C$6:$AP$25,A25)>0,"",A25),"")
A26: =IFERROR(__xludf.DUMMYFUNCTION("IFERROR(REGEXEXTRACT('Manual Data Import'!B26, ""^(.*)\s+[A-Z]{2,4}\s+\(\d+\)$""),'Manual Data Import'!B26) & CHAR(10) & IFERROR(REGEXREPLACE('Manual Data Import'!C26, ""\d+$"", """")) &"" - ""& IFERROR(REGEXEXTRACT('Manual Data Import'!B26, ""([A-Z]{2,"&"4})\s+\(\d+\)$"")) & "" (""& IFERROR(REGEXEXTRACT('Manual Data Import'!B26, ""\((\d+)\)"")) & "")"""),"George Pickens WR - DAL (14)") -> George Pickens WR - DAL (14) | B26: =IFERROR(IF(COUNTIF('Draft Board'!$C$3:$V$24,A26)+COUNTIF(Keepers!$B$2:$U$21,A26)+COUNTIF('Auction Draft Board'!$C$6:$AP$25,A26)>0,"",A26),"")
A27: =IFERROR(__xludf.DUMMYFUNCTION("IFERROR(REGEXEXTRACT('Manual Data Import'!B27, ""^(.*)\s+[A-Z]{2,4}\s+\(\d+\)$""),'Manual Data Import'!B27) & CHAR(10) & IFERROR(REGEXREPLACE('Manual Data Import'!C27, ""\d+$"", """")) &"" - ""& IFERROR(REGEXEXTRACT('Manual Data Import'!B27, ""([A-Z]{2,"&"4})\s+\(\d+\)$"")) & "" (""& IFERROR(REGEXEXTRACT('Manual Data Import'!B27, ""\((\d+)\)"")) & "")"""),"Rashee Rice WR - KC (5)") -> Rashee Rice WR - KC (5) | B27: =IFERROR(IF(COUNTIF('Draft Board'!$C$3:$V$24,A27)+COUNTIF(Keepers!$B$2:$U$21,A27)+COUNTIF('Auction Draft Board'!$C$6:$AP$25,A27)>0,"",A27),"")
A28: =IFERROR(__xludf.DUMMYFUNCTION("IFERROR(REGEXEXTRACT('Manual Data Import'!B28, ""^(.*)\s+[A-Z]{2,4}\s+\(\d+\)$""),'Manual Data Import'!B28) & CHAR(10) & IFERROR(REGEXREPLACE('Manual Data Import'!C28, ""\d+$"", """")) &"" - ""& IFERROR(REGEXEXTRACT('Manual Data Import'!B28, ""([A-Z]{2,"&"4})\s+\(\d+\)$"")) & "" (""& IFERROR(REGEXEXTRACT('Manual Data Import'!B28, ""\((\d+)\)"")) & "")"""),"Chris Olave WR - NO (8)") -> Chris Olave WR - NO (8) | B28: =IFERROR(IF(COUNTIF('Draft Board'!$C$3:$V$24,A28)+COUNTIF(Keepers!$B$2:$U$21,A28)+COUNTIF('Auction Draft Board'!$C$6:$AP$25,A28)>0,"",A28),"")
A29: =IFERROR(__xludf.DUMMYFUNCTION("IFERROR(REGEXEXTRACT('Manual Data Import'!B29, ""^(.*)\s+[A-Z]{2,4}\s+\(\d+\)$""),'Manual Data Import'!B29) & CHAR(10) & IFERROR(REGEXREPLACE('Manual Data Import'!C29, ""\d+$"", """")) &"" - ""& IFERROR(REGEXEXTRACT('Manual Data Import'!B29, ""([A-Z]{2,"&"4})\s+\(\d+\)$"")) & "" (""& IFERROR(REGEXEXTRACT('Manual Data Import'!B29, ""\((\d+)\)"")) & "")"""),"Jeremiyah Love RB - ARI (14)") -> Jeremiyah Love RB - ARI (14) | B29: =IFERROR(IF(COUNTIF('Draft Board'!$C$3:$V$24,A29)+COUNTIF(Keepers!$B$2:$U$21,A29)+COUNTIF('Auction Draft Board'!$C$6:$AP$25,A29)>0,"",A29),"")
A30: =IFERROR(__xludf.DUMMYFUNCTION("IFERROR(REGEXEXTRACT('Manual Data Import'!B30, ""^(.*)\s+[A-Z]{2,4}\s+\(\d+\)$""),'Manual Data Import'!B30) & CHAR(10) & IFERROR(REGEXREPLACE('Manual Data Import'!C30, ""\d+$"", """")) &"" - ""& IFERROR(REGEXEXTRACT('Manual Data Import'!B30, ""([A-Z]{2,"&"4})\s+\(\d+\)$"")) & "" (""& IFERROR(REGEXEXTRACT('Manual Data Import'!B30, ""\((\d+)\)"")) & "")"""),"Malik Nabers WR - NYG (8)") -> Malik Nabers WR - NYG (8) | B30: =IFERROR(IF(COUNTIF('Draft Board'!$C$3:$V$24,A30)+COUNTIF(Keepers!$B$2:$U$21,A30)+COUNTIF('Auction Draft Board'!$C$6:$AP$25,A30)>0,"",A30),"")
A31: =IFERROR(__xludf.DUMMYFUNCTION("IFERROR(REGEXEXTRACT('Manual Data Import'!B31, ""^(.*)\s+[A-Z]{2,4}\s+\(\d+\)$""),'Manual Data Import'!B31) & CHAR(10) & IFERROR(REGEXREPLACE('Manual Data Import'!C31, ""\d+$"", """")) &"" - ""& IFERROR(REGEXEXTRACT('Manual Data Import'!B31, ""([A-Z]{2,"&"4})\s+\(\d+\)$"")) & "" (""& IFERROR(REGEXEXTRACT('Manual Data Import'!B31, ""\((\d+)\)"")) & "")"""),"Kyren Williams RB - LAR (11)") -> Kyren Williams RB - LAR (11) | B31: =IFERROR(IF(COUNTIF('Draft Board'!$C$3:$V$24,A31)+COUNTIF(Keepers!$B$2:$U$21,A31)+COUNTIF('Auction Draft Board'!$C$6:$AP$25,A31)>0,"",A31),"")
A32: =IFERROR(__xludf.DUMMYFUNCTION("IFERROR(REGEXEXTRACT('Manual Data Import'!B32, ""^(.*)\s+[A-Z]{2,4}\s+\(\d+\)$""),'Manual Data Import'!B32) & CHAR(10) & IFERROR(REGEXREPLACE('Manual Data Import'!C32, ""\d+$"", """")) &"" - ""& IFERROR(REGEXEXTRACT('Manual Data Import'!B32, ""([A-Z]{2,"&"4})\s+\(\d+\)$"")) & "" (""& IFERROR(REGEXEXTRACT('Manual Data Import'!B32, ""\((\d+)\)"")) & "")"""),"Javonte Williams RB - DAL (14)") -> Javonte Williams RB - DAL (14) | B32: =IFERROR(IF(COUNTIF('Draft Board'!$C$3:$V$24,A32)+COUNTIF(Keepers!$B$2:$U$21,A32)+COUNTIF('Auction Draft Board'!$C$6:$AP$25,A32)>0,"",A32),"")
A33: =IFERROR(__xludf.DUMMYFUNCTION("IFERROR(REGEXEXTRACT('Manual Data Import'!B33, ""^(.*)\s+[A-Z]{2,4}\s+\(\d+\)$""),'Manual Data Import'!B33) & CHAR(10) & IFERROR(REGEXREPLACE('Manual Data Import'!C33, ""\d+$"", """")) &"" - ""& IFERROR(REGEXEXTRACT('Manual Data Import'!B33, ""([A-Z]{2,"&"4})\s+\(\d+\)$"")) & "" (""& IFERROR(REGEXEXTRACT('Manual Data Import'!B33, ""\((\d+)\)"")) & "")"""),"Josh Jacobs RB - GB (11)") -> Josh Jacobs RB - GB (11) | B33: =IFERROR(IF(COUNTIF('Draft Board'!$C$3:$V$24,A33)+COUNTIF(Keepers!$B$2:$U$21,A33)+COUNTIF('Auction Draft Board'!$C$6:$AP$25,A33)>0,"",A33),"")
A34: =IFERROR(__xludf.DUMMYFUNCTION("IFERROR(REGEXEXTRACT('Manual Data Import'!B34, ""^(.*)\s+[A-Z]{2,4}\s+\(\d+\)$""),'Manual Data Import'!B34) & CHAR(10) & IFERROR(REGEXREPLACE('Manual Data Import'!C34, ""\d+$"", """")) &"" - ""& IFERROR(REGEXEXTRACT('Manual Data Import'!B34, ""([A-Z]{2,"&"4})\s+\(\d+\)$"")) & "" (""& IFERROR(REGEXEXTRACT('Manual Data Import'!B34, ""\((\d+)\)"")) & "")"""),"Breece Hall RB - NYJ (13)") -> Breece Hall RB - NYJ (13) | B34: =IFERROR(IF(COUNTIF('Draft Board'!$C$3:$V$24,A34)+COUNTIF(Keepers!$B$2:$U$21,A34)+COUNTIF('Auction Draft Board'!$C$6:$AP$25,A34)>0,"",A34),"")
A35: =IFERROR(__xludf.DUMMYFUNCTION("IFERROR(REGEXEXTRACT('Manual Data Import'!B35, ""^(.*)\s+[A-Z]{2,4}\s+\(\d+\)$""),'Manual Data Import'!B35) & CHAR(10) & IFERROR(REGEXREPLACE('Manual Data Import'!C35, ""\d+$"", """")) &"" - ""& IFERROR(REGEXEXTRACT('Manual Data Import'!B35, ""([A-Z]{2,"&"4})\s+\(\d+\)$"")) & "" (""& IFERROR(REGEXEXTRACT('Manual Data Import'!B35, ""\((\d+)\)"")) & "")"""),"DeVonta Smith WR - PHI (10)") -> DeVonta Smith WR - PHI (10) | B35: =IFERROR(IF(COUNTIF('Draft Board'!$C$3:$V$24,A35)+COUNTIF(Keepers!$B$2:$U$21,A35)+COUNTIF('Auction Draft Board'!$C$6:$AP$25,A35)>0,"",A35),"")
A36: =IFERROR(__xludf.DUMMYFUNCTION("IFERROR(REGEXEXTRACT('Manual Data Import'!B36, ""^(.*)\s+[A-Z]{2,4}\s+\(\d+\)$""),'Manual Data Import'!B36) & CHAR(10) & IFERROR(REGEXREPLACE('Manual Data Import'!C36, ""\d+$"", """")) &"" - ""& IFERROR(REGEXEXTRACT('Manual Data Import'!B36, ""([A-Z]{2,"&"4})\s+\(\d+\)$"")) & "" (""& IFERROR(REGEXEXTRACT('Manual Data Import'!B36, ""\((\d+)\)"")) & "")"""),"Zay Flowers WR - BAL (13)") -> Zay Flowers WR - BAL (13) | B36: =IFERROR(IF(COUNTIF('Draft Board'!$C$3:$V$24,A36)+COUNTIF(Keepers!$B$2:$U$21,A36)+COUNTIF('Auction Draft Board'!$C$6:$AP$25,A36)>0,"",A36),"")
A37: =IFERROR(__xludf.DUMMYFUNCTION("IFERROR(REGEXEXTRACT('Manual Data Import'!B37, ""^(.*)\s+[A-Z]{2,4}\s+\(\d+\)$""),'Manual Data Import'!B37) & CHAR(10) & IFERROR(REGEXREPLACE('Manual Data Import'!C37, ""\d+$"", """")) &"" - ""& IFERROR(REGEXEXTRACT('Manual Data Import'!B37, ""([A-Z]{2,"&"4})\s+\(\d+\)$"")) & "" (""& IFERROR(REGEXEXTRACT('Manual Data Import'!B37, ""\((\d+)\)"")) & "")"""),"Travis Etienne Jr. RB - NO (8)") -> Travis Etienne Jr. RB - NO (8) | B37: =IFERROR(IF(COUNTIF('Draft Board'!$C$3:$V$24,A37)+COUNTIF(Keepers!$B$2:$U$21,A37)+COUNTIF('Auction Draft Board'!$C$6:$AP$25,A37)>0,"",A37),"")
A38: =IFERROR(__xludf.DUMMYFUNCTION("IFERROR(REGEXEXTRACT('Manual Data Import'!B38, ""^(.*)\s+[A-Z]{2,4}\s+\(\d+\)$""),'Manual Data Import'!B38) & CHAR(10) & IFERROR(REGEXREPLACE('Manual Data Import'!C38, ""\d+$"", """")) &"" - ""& IFERROR(REGEXEXTRACT('Manual Data Import'!B38, ""([A-Z]{2,"&"4})\s+\(\d+\)$"")) & "" (""& IFERROR(REGEXEXTRACT('Manual Data Import'!B38, ""\((\d+)\)"")) & "")"""),"Cam Skattebo RB - NYG (8)") -> Cam Skattebo RB - NYG (8) | B38: =IFERROR(IF(COUNTIF('Draft Board'!$C$3:$V$24,A38)+COUNTIF(Keepers!$B$2:$U$21,A38)+COUNTIF('Auction Draft Board'!$C$6:$AP$25,A38)>0,"",A38),"")
A39: =IFERROR(__xludf.DUMMYFUNCTION("IFERROR(REGEXEXTRACT('Manual Data Import'!B39, ""^(.*)\s+[A-Z]{2,4}\s+\(\d+\)$""),'Manual Data Import'!B39) & CHAR(10) & IFERROR(REGEXREPLACE('Manual Data Import'!C39, ""\d+$"", """")) &"" - ""& IFERROR(REGEXEXTRACT('Manual Data Import'!B39, ""([A-Z]{2,"&"4})\s+\(\d+\)$"")) & "" (""& IFERROR(REGEXEXTRACT('Manual Data Import'!B39, ""\((\d+)\)"")) & "")"""),"Tetairoa McMillan WR - CAR (5)") -> Tetairoa McMillan WR - CAR (5) | B39: =IFERROR(IF(COUNTIF('Draft Board'!$C$3:$V$24,A39)+COUNTIF(Keepers!$B$2:$U$21,A39)+COUNTIF('Auction Draft Board'!$C$6:$AP$25,A39)>0,"",A39),"")
A40: =IFERROR(__xludf.DUMMYFUNCTION("IFERROR(REGEXEXTRACT('Manual Data Import'!B40, ""^(.*)\s+[A-Z]{2,4}\s+\(\d+\)$""),'Manual Data Import'!B40) & CHAR(10) & IFERROR(REGEXREPLACE('Manual Data Import'!C40, ""\d+$"", """")) &"" - ""& IFERROR(REGEXEXTRACT('Manual Data Import'!B40, ""([A-Z]{2,"&"4})\s+\(\d+\)$"")) & "" (""& IFERROR(REGEXEXTRACT('Manual Data Import'!B40, ""\((\d+)\)"")) & "")"""),"Garrett Wilson WR - NYJ (13)") -> Garrett Wilson WR - NYJ (13) | B40: =IFERROR(IF(COUNTIF('Draft Board'!$C$3:$V$24,A40)+COUNTIF(Keepers!$B$2:$U$21,A40)+COUNTIF('Auction Draft Board'!$C$6:$AP$25,A40)>0,"",A40),"")
...

Sheet Misc
A1: 1 | B1: 2 | C1: 3 | D1: 4 | E1: 5 | F1: 6 | G1: 7 | H1: 8 | I1: 9 | J1: 10 | K1: 11 | L1: 12 | M1: 13 | N1: 14 | O1: 15 | P1: 16 | Q1: 17 | R1: 18 | S1: 19 | T1: 20 | V1: =IF(ISBLANK('Draft Board'!C3),A1,"") -> 1 | W1: =IF(ISBLANK('Draft Board'!D3),B1,"") -> 2 | X1: =IF(ISBLANK('Draft Board'!E3),C1,"") -> 3 | Y1: =IF(ISBLANK('Draft Board'!F3),D1,"") -> 4 | Z1: =IF(ISBLANK('Draft Board'!G3),E1,"") -> 5 | AA1: =IF(ISBLANK('Draft Board'!H3),F1,"") -> 6 | AB1: =IF(ISBLANK('Draft Board'!I3),G1,"") -> 7 | AC1: =IF(ISBLANK('Draft Board'!J3),H1,"") -> 8 | ... AO1: =IF(ISBLANK('Draft Board'!V3),T1,"") -> 20
A2: 40 | B2: 39 | C2: 38 | D2: 37 | E2: 36 | F2: 35 | G2: 34 | H2: 33 | I2: 32 | J2: 31 | K2: 30 | L2: 29 | M2: 28 | N2: 27 | O2: 26 | P2: 25 | Q2: 24 | R2: 23 | S2: 22 | T2: 21 | V2: =IF(ISBLANK('Draft Board'!C4),A2,"") -> 40 | W2: =IF(ISBLANK('Draft Board'!D4),B2,"") -> 39 | X2: =IF(ISBLANK('Draft Board'!E4),C2,"") -> 38 | Y2: =IF(ISBLANK('Draft Board'!F4),D2,"") -> 37 | Z2: =IF(ISBLANK('Draft Board'!G4),E2,"") -> 36 | AA2: =IF(ISBLANK('Draft Board'!H4),F2,"") -> 35 | AB2: =IF(ISBLANK('Draft Board'!I4),G2,"") -> 34 | AC2: =IF(ISBLANK('Draft Board'!J4),H2,"") -> 33 | ... AO2: =IF(ISBLANK('Draft Board'!V4),T2,"") -> 21
A3: 41 | B3: 42 | C3: 43 | D3: 44 | E3: 45 | F3: 46 | G3: 47 | H3: 48 | I3: 49 | J3: 50 | K3: 51 | L3: 52 | M3: 53 | N3: 54 | O3: 55 | P3: 56 | Q3: 57 | R3: 58 | S3: 59 | T3: 60 | V3: =IF(ISBLANK('Draft Board'!C5),A3,"") -> 41 | W3: =IF(ISBLANK('Draft Board'!D5),B3,"") -> 42 | X3: =IF(ISBLANK('Draft Board'!E5),C3,"") -> 43 | Y3: =IF(ISBLANK('Draft Board'!F5),D3,"") -> 44 | Z3: =IF(ISBLANK('Draft Board'!G5),E3,"") -> 45 | AA3: =IF(ISBLANK('Draft Board'!H5),F3,"") -> 46 | AB3: =IF(ISBLANK('Draft Board'!I5),G3,"") -> 47 | AC3: =IF(ISBLANK('Draft Board'!J5),H3,"") -> 48 | ... AO3: =IF(ISBLANK('Draft Board'!V5),T3,"") -> 60
A4: 80 | B4: 79 | C4: 78 | D4: 77 | E4: 76 | F4: 75 | G4: 74 | H4: 73 | I4: 72 | J4: 71 | K4: 70 | L4: 69 | M4: 68 | N4: 67 | O4: 66 | P4: 65 | Q4: 64 | R4: 63 | S4: 62 | T4: 61 | V4: =IF(ISBLANK('Draft Board'!C6),A4,"") -> 80 | W4: =IF(ISBLANK('Draft Board'!D6),B4,"") -> 79 | X4: =IF(ISBLANK('Draft Board'!E6),C4,"") -> 78 | Y4: =IF(ISBLANK('Draft Board'!F6),D4,"") -> 77 | Z4: =IF(ISBLANK('Draft Board'!G6),E4,"") -> 76 | AA4: =IF(ISBLANK('Draft Board'!H6),F4,"") -> 75 | AB4: =IF(ISBLANK('Draft Board'!I6),G4,"") -> 74 | AC4: =IF(ISBLANK('Draft Board'!J6),H4,"") -> 73 | ... AO4: =IF(ISBLANK('Draft Board'!V6),T4,"") -> 61
A5: 81 | B5: 82 | C5: 83 | D5: 84 | E5: 85 | F5: 86 | G5: 87 | H5: 88 | I5: 89 | J5: 90 | K5: 91 | L5: 92 | M5: 93 | N5: 94 | O5: 95 | P5: 96 | Q5: 97 | R5: 98 | S5: 99 | T5: 100 | V5: =IF(ISBLANK('Draft Board'!C7),A5,"") -> 81 | W5: =IF(ISBLANK('Draft Board'!D7),B5,"") -> 82 | X5: =IF(ISBLANK('Draft Board'!E7),C5,"") -> 83 | Y5: =IF(ISBLANK('Draft Board'!F7),D5,"") -> 84 | Z5: =IF(ISBLANK('Draft Board'!G7),E5,"") -> 85 | AA5: =IF(ISBLANK('Draft Board'!H7),F5,"") -> 86 | AB5: =IF(ISBLANK('Draft Board'!I7),G5,"") -> 87 | AC5: =IF(ISBLANK('Draft Board'!J7),H5,"") -> 88 | ... AO5: =IF(ISBLANK('Draft Board'!V7),T5,"") -> 100
A6: 120 | B6: 119 | C6: 118 | D6: 117 | E6: 116 | F6: 115 | G6: 114 | H6: 113 | I6: 112 | J6: 111 | K6: 110 | L6: 109 | M6: 108 | N6: 107 | O6: 106 | P6: 105 | Q6: 104 | R6: 103 | S6: 102 | T6: 101 | V6: =IF(ISBLANK('Draft Board'!C8),A6,"") -> 120 | W6: =IF(ISBLANK('Draft Board'!D8),B6,"") -> 119 | X6: =IF(ISBLANK('Draft Board'!E8),C6,"") -> 118 | Y6: =IF(ISBLANK('Draft Board'!F8),D6,"") -> 117 | Z6: =IF(ISBLANK('Draft Board'!G8),E6,"") -> 116 | AA6: =IF(ISBLANK('Draft Board'!H8),F6,"") -> 115 | AB6: =IF(ISBLANK('Draft Board'!I8),G6,"") -> 114 | AC6: =IF(ISBLANK('Draft Board'!J8),H6,"") -> 113 | ... AO6: =IF(ISBLANK('Draft Board'!V8),T6,"") -> 101
A7: 121 | B7: 122 | C7: 123 | D7: 124 | E7: 125 | F7: 126 | G7: 127 | H7: 128 | I7: 129 | J7: 130 | K7: 131 | L7: 132 | M7: 133 | N7: 134 | O7: 135 | P7: 136 | Q7: 137 | R7: 138 | S7: 139 | T7: 140 | V7: =IF(ISBLANK('Draft Board'!C9),A7,"") -> 121 | W7: =IF(ISBLANK('Draft Board'!D9),B7,"") -> 122 | X7: =IF(ISBLANK('Draft Board'!E9),C7,"") -> 123 | Y7: =IF(ISBLANK('Draft Board'!F9),D7,"") -> 124 | Z7: =IF(ISBLANK('Draft Board'!G9),E7,"") -> 125 | AA7: =IF(ISBLANK('Draft Board'!H9),F7,"") -> 126 | AB7: =IF(ISBLANK('Draft Board'!I9),G7,"") -> 127 | AC7: =IF(ISBLANK('Draft Board'!J9),H7,"") -> 128 | ... AO7: =IF(ISBLANK('Draft Board'!V9),T7,"") -> 140
A8: 160 | B8: 159 | C8: 158 | D8: 157 | E8: 156 | F8: 155 | G8: 154 | H8: 153 | I8: 152 | J8: 151 | K8: 150 | L8: 149 | M8: 148 | N8: 147 | O8: 146 | P8: 145 | Q8: 144 | R8: 143 | S8: 142 | T8: 141 | V8: =IF(ISBLANK('Draft Board'!C10),A8,"") -> 160 | W8: =IF(ISBLANK('Draft Board'!D10),B8,"") -> 159 | X8: =IF(ISBLANK('Draft Board'!E10),C8,"") -> 158 | Y8: =IF(ISBLANK('Draft Board'!F10),D8,"") -> 157 | Z8: =IF(ISBLANK('Draft Board'!G10),E8,"") -> 156 | AA8: =IF(ISBLANK('Draft Board'!H10),F8,"") -> 155 | AB8: =IF(ISBLANK('Draft Board'!I10),G8,"") -> 154 | AC8: =IF(ISBLANK('Draft Board'!J10),H8,"") -> 153 | ... AO8: =IF(ISBLANK('Draft Board'!V10),T8,"") -> 141
A9: 161 | B9: 162 | C9: 163 | D9: 164 | E9: 165 | F9: 166 | G9: 167 | H9: 168 | I9: 169 | J9: 170 | K9: 171 | L9: 172 | M9: 173 | N9: 174 | O9: 175 | P9: 176 | Q9: 177 | R9: 178 | S9: 179 | T9: 180 | V9: =IF(ISBLANK('Draft Board'!C11),A9,"") -> 161 | W9: =IF(ISBLANK('Draft Board'!D11),B9,"") -> 162 | X9: =IF(ISBLANK('Draft Board'!E11),C9,"") -> 163 | Y9: =IF(ISBLANK('Draft Board'!F11),D9,"") -> 164 | Z9: =IF(ISBLANK('Draft Board'!G11),E9,"") -> 165 | AA9: =IF(ISBLANK('Draft Board'!H11),F9,"") -> 166 | AB9: =IF(ISBLANK('Draft Board'!I11),G9,"") -> 167 | AC9: =IF(ISBLANK('Draft Board'!J11),H9,"") -> 168 | ... AO9: =IF(ISBLANK('Draft Board'!V11),T9,"") -> 180
A10: 200 | B10: 199 | C10: 198 | D10: 197 | E10: 196 | F10: 195 | G10: 194 | H10: 193 | I10: 192 | J10: 191 | K10: 190 | L10: 189 | M10: 188 | N10: 187 | O10: 186 | P10: 185 | Q10: 184 | R10: 183 | S10: 182 | T10: 181 | V10: =IF(ISBLANK('Draft Board'!C12),A10,"") -> 200 | W10: =IF(ISBLANK('Draft Board'!D12),B10,"") -> 199 | X10: =IF(ISBLANK('Draft Board'!E12),C10,"") -> 198 | Y10: =IF(ISBLANK('Draft Board'!F12),D10,"") -> 197 | Z10: =IF(ISBLANK('Draft Board'!G12),E10,"") -> 196 | AA10: =IF(ISBLANK('Draft Board'!H12),F10,"") -> 195 | AB10: =IF(ISBLANK('Draft Board'!I12),G10,"") -> 194 | AC10: =IF(ISBLANK('Draft Board'!J12),H10,"") -> 193 | ... AO10: =IF(ISBLANK('Draft Board'!V12),T10,"") -> 181
A11: 201 | B11: 202 | C11: 203 | D11: 204 | E11: 205 | F11: 206 | G11: 207 | H11: 208 | I11: 209 | J11: 210 | K11: 211 | L11: 212 | M11: 213 | N11: 214 | O11: 215 | P11: 216 | Q11: 217 | R11: 218 | S11: 219 | T11: 220 | V11: =IF(ISBLANK('Draft Board'!C13),A11,"") -> 201 | W11: =IF(ISBLANK('Draft Board'!D13),B11,"") -> 202 | X11: =IF(ISBLANK('Draft Board'!E13),C11,"") -> 203 | Y11: =IF(ISBLANK('Draft Board'!F13),D11,"") -> 204 | Z11: =IF(ISBLANK('Draft Board'!G13),E11,"") -> 205 | AA11: =IF(ISBLANK('Draft Board'!H13),F11,"") -> 206 | AB11: =IF(ISBLANK('Draft Board'!I13),G11,"") -> 207 | AC11: =IF(ISBLANK('Draft Board'!J13),H11,"") -> 208 | ... AO11: =IF(ISBLANK('Draft Board'!V13),T11,"") -> 220
A12: 240 | B12: 239 | C12: 238 | D12: 237 | E12: 236 | F12: 235 | G12: 234 | H12: 233 | I12: 232 | J12: 231 | K12: 230 | L12: 229 | M12: 228 | N12: 227 | O12: 226 | P12: 225 | Q12: 224 | R12: 223 | S12: 222 | T12: 221 | V12: =IF(ISBLANK('Draft Board'!C14),A12,"") -> 240 | W12: =IF(ISBLANK('Draft Board'!D14),B12,"") -> 239 | X12: =IF(ISBLANK('Draft Board'!E14),C12,"") -> 238 | Y12: =IF(ISBLANK('Draft Board'!F14),D12,"") -> 237 | Z12: =IF(ISBLANK('Draft Board'!G14),E12,"") -> 236 | AA12: =IF(ISBLANK('Draft Board'!H14),F12,"") -> 235 | AB12: =IF(ISBLANK('Draft Board'!I14),G12,"") -> 234 | AC12: =IF(ISBLANK('Draft Board'!J14),H12,"") -> 233 | ... AO12: =IF(ISBLANK('Draft Board'!V14),T12,"") -> 221
... A18: 360 | B18: 359 | C18: 358 | D18: 357 | E18: 356 | F18: 355 | G18: 354 | H18: 353 | I18: 352 | J18: 351 | K18: 350 | L18: 349 | M18: 348 | N18: 347 | O18: 346 | P18: 345 | Q18: 344 | R18: 343 | S18: 342 | T18: 341 | V18: =IF(ISBLANK('Draft Board'!C20),A18,"") -> 360 | W18: =IF(ISBLANK('Draft Board'!D20),B18,"") -> 359 | X18: =IF(ISBLANK('Draft Board'!E20),C18,"") -> 358 | Y18: =IF(ISBLANK('Draft Board'!F20),D18,"") -> 357 | Z18: =IF(ISBLANK('Draft Board'!G20),E18,"") -> 356 | AA18: =IF(ISBLANK('Draft Board'!H20),F18,"") -> 355 | AB18: =IF(ISBLANK('Draft Board'!I20),G18,"") -> 354 | AC18: =IF(ISBLANK('Draft Board'!J20),H18,"") -> 353 | ... AO18: =IF(ISBLANK('Draft Board'!V20),T18,"") -> 341
A19: 361 | B19: 362 | C19: 363 | D19: 364 | E19: 365 | F19: 366 | G19: 367 | H19: 368 | I19: 369 | J19: 370 | K19: 371 | L19: 372 | M19: 373 | N19: 374 | O19: 375 | P19: 376 | Q19: 377 | R19: 378 | S19: 379 | T19: 380 | V19: =IF(ISBLANK('Draft Board'!C23),A19,"") -> 361 | W19: =IF(ISBLANK('Draft Board'!D23),B19,"") -> 362 | X19: =IF(ISBLANK('Draft Board'!E23),C19,"") -> 363 | Y19: =IF(ISBLANK('Draft Board'!F23),D19,"") -> 364 | Z19: =IF(ISBLANK('Draft Board'!G23),E19,"") -> 365 | AA19: =IF(ISBLANK('Draft Board'!H23),F19,"") -> 366 | AB19: =IF(ISBLANK('Draft Board'!I23),G19,"") -> 367 | AC19: =IF(ISBLANK('Draft Board'!J23),H19,"") -> 368 | ... AO19: =IF(ISBLANK('Draft Board'!V23),T19,"") -> 380
A20: 400 | B20: 399 | C20: 398 | D20: 397 | E20: 396 | F20: 395 | G20: 394 | H20: 393 | I20: 392 | J20: 391 | K20: 390 | L20: 389 | M20: 388 | N20: 387 | O20: 386 | P20: 385 | Q20: 384 | R20: 383 | S20: 382 | T20: 381 | V20: =IF(ISBLANK(#REF!),A20,"") | W20: =IF(ISBLANK(#REF!),B20,"") | X20: =IF(ISBLANK(#REF!),C20,"") | Y20: =IF(ISBLANK(#REF!),D20,"") | Z20: =IF(ISBLANK(#REF!),E20,"") | AA20: =IF(ISBLANK(#REF!),F20,"") | AB20: =IF(ISBLANK(#REF!),G20,"") | AC20: =IF(ISBLANK(#REF!),H20,"") | ... AO20: =IF(ISBLANK(#REF!),T20,"")
A22: Standard | B22: https://www.fantasypros.com/nfl/adp/overall.php | V22: =IF(MIN(V1:V20)=0,"",MIN(V1:V20)) -> 1 | W22: =IF(MIN(W1:W20)=0,"",MIN(W1:W20)) -> 2 | X22: =IF(MIN(X1:X20)=0,"",MIN(X1:X20)) -> 3 | Y22: =IF(MIN(Y1:Y20)=0,"",MIN(Y1:Y20)) -> 4 | Z22: =IF(MIN(Z1:Z20)=0,"",MIN(Z1:Z20)) -> 5 | AA22: =IF(MIN(AA1:AA20)=0,"",MIN(AA1:AA20)) -> 6 | AB22: =IF(MIN(AB1:AB20)=0,"",MIN(AB1:AB20)) -> 7 | AC22: =IF(MIN(AC1:AC20)=0,"",MIN(AC1:AC20)) -> 8 | ... AO22: =IF(MIN(AO1:AO20)=0,"",MIN(AO1:AO20)) -> 20
A23: PPR | B23: https://www.fantasypros.com/nfl/adp/ppr-overall.php | V23: =IFERROR('Draft Board'!C2,"") -> Team 1 | W23: =IFERROR('Draft Board'!D2,"") -> Team 2 | X23: =IFERROR('Draft Board'!E2,"") -> Team 3 | Y23: =IFERROR('Draft Board'!F2,"") -> Team 4 | Z23: =IFERROR('Draft Board'!G2,"") -> Team 5 | AA23: =IFERROR('Draft Board'!H2,"") -> Team 6 | AB23: =IFERROR('Draft Board'!I2,"") -> Team 7 | AC23: =IFERROR('Draft Board'!J2,"") -> Team 8 | ... AO23: =IFERROR('Draft Board'!V2,"") -> Team 20
A24: Half-PPR | B24: https://www.fantasypros.com/nfl/adp/half-point-ppr-overall.php
A25: Rookies | B25: https://www.fantasypros.com/nfl/adp/rookies.php | V25: Next Team: | W25: =HLOOKUP(MIN(V22:AO22),V22:AO23,2,0) -> Team 1 | Y25: Rounds:
A26: Offline Backup

Sheet About
A1: SmartDraft
A2: Creted By | B2: https://www.reddit.com/u/basmith7
A3: Reddit Post
